Workbook

Sheet Invoices
A1: Invoice No | B1: Customer | C1: Site | D1: Invoice Date | E1: Due Date | F1: Amount | G1: Remarks
A2: ALL-2026-001 | B2: Bluewave Hotels Pvt Ltd | C2: Bluewave - Indiranagar | D2: 46275 | E2: 46305 | F2: 50000 | G2: TDS 2% | not due (in 20 days) | nothing paid
A3: ALL-2026-002 | B3: Kaveri Tech Park LLP | C3: Kaveri - Block 1 | D3: 46280 | E3: 46310 | F3: 100000 | G3: TDS 10% | not due (in 25 days) | partial cash + TDS
A4: ALL-2026-003 | B4: Green Meadow School | C4: Green Meadow - Main Campus | D4: 46280 | E4: 46315 | F4: 27500 | G4: TDS 1.5% | not due (in 30 days) | nothing paid
A5: ALL-2026-004 | B5: Sunrise Apartments Owners Assn | C5: Sunrise - Tower A | D5: 46270 | E5: 46300 | F5: 12500 | G5: No TDS customer | not due | nothing paid
A6: ALL-2026-005 | B6: Café Zoë & Sons (Pvt) Ltd | C6: Café Zoë - Main Outlet | D6: 46282 | E6: 46330 | F6: 8750.75 | G6: No TDS customer | decimals | nothing paid
A7: ALL-2026-006 | B7: Bluewave Hotels Pvt Ltd | C7: Bluewave - Whitefield | D7: 46145 | E7: 46175 | F7: 80000 | G7: TDS 2% | OVERDUE 110 days | nothing paid
A8: ALL-2026-007 | B8: Kaveri Tech Park LLP | C8: Kaveri - Block 2 | D8: 46195 | E8: 46225 | F8: 150000 | G8: TDS 10% | OVERDUE 60 days | nothing paid
A9: ALL-2026-008 | B9: Lotus Diagnostics Centre | C9: Lotus - Jayanagar Lab | D9: 46225 | E9: 46255 | F9: 45000 | G9: TDS 2% | OVERDUE 30 days | nothing paid
A10: ALL-2026-009 | B10: Green Meadow School | C10: Green Meadow - Annex | D10: 46245 | E10: 46275 | F10: 33340 | G10: TDS 1.5% | OVERDUE 10 days | nothing paid
A11: ALL-2026-010 | B11: Sunrise Apartments Owners Assn | C11: Sunrise - Tower B | D11: 46254 | E11: 46284 | F11: 18000 | G11: No TDS customer | OVERDUE by 1 day
A12: ALL-2026-011 | B12: Café Zoë & Sons (Pvt) Ltd | C12: Café Zoë - Kiosk 2 | D12: 46210 | E12: 46240 | F12: 6400 | G12: No TDS customer | OVERDUE 45 days
A13: ALL-2026-012 | B13: Lotus Diagnostics Centre | C13: Lotus - HSR Lab | D13: 46255 | E13: 46285 | F13: 27500 | G13: Due TODAY | TDS 2%
... A43: ALL-2026-042 | B43: BLUEWAVE HOTELS PVT LTD | C43: bluewave - whitefield | D43: 46273 | E43: 46303 | F43: 12000 | G43: Customer in capitals with spaces, site in lower case

Sheet Test Plan
A1: Test plan: what each invoice in the 'Invoices' sheet is for, and what you should see (numbers are calculated)
A2: Reference date (today of the test) | B2: 46285
A4: Case | B4: Invoice No | C4: Scenario | D4: Customer | E4: Site | F4: TDS rate % | G4: Due date | H4: Days late (+) / left (-) | I4: Status right after upload | J4: Amount (Rs) | K4: Expected TDS (Rs) | L4: Cash paid (Rs) | M4: TDS deducted (Rs) | N4: Settled (Rs) | O4: Pending after payments (Rs) | P4: Final invoice status | Q4: TDS pending (Rs) | R4: Final TDS status | S4: Payments | T4: What to do | U4: Later action
A5: 1 | B5: =Invoices!A2 -> ALL-2026-001 | C5: TDS 2% | not due (in 20 days) | nothing paid | D5: =Invoices!B2 -> Bluewave Hotels Pvt Ltd | E5: =Invoices!C2 -> Bluewave - Indiranagar | F5: =IFERROR(INDEX(Customers!$F$4:$F$13,MATCH(TRIM(D5),Customers!$B$4:$B$13,0)),IFERROR(INDEX(Customers!$F$4:$F$13,MATCH(TRIM(D5),Customers!$C$4:$C$13,0)),0)) -> 2 | G5: =Invoices!E2 -> 46305 | H5: =$B$2-G5 -> -20 | I5: =IF(G5<$B$2,"OVERDUE","PENDING") -> PENDING | J5: =Invoices!F2 -> 50000 | K5: =ROUND(J5*F5/100,2) -> 1000 | L5: =SUMIFS('Payment Lines'!$C$4:$C$60,'Payment Lines'!$B$4:$B$60,B5) -> 0 | M5: =SUMIFS('Payment Lines'!$D$4:$D$60,'Payment Lines'!$B$4:$B$60,B5) -> 0 | N5: =ROUND(L5+SUMIFS('Payment Lines'!$D$4:$D$60,'Payment Lines'!$B$4:$B$60,B5,'Payment Lines'!$E$4:$E$60,"CURRENT"),2) -> 0 | O5: =IF(U5="CANCEL",J5,ROUND(J5-N5,2)) -> 50000 | P5: =IF(U5="CANCEL","CANCELLED",IF(O5<=0,"PAID",IF(G5<$B$2,"OVERDUE",IF(N5>0,"PARTIAL","PENDING")))) -> PENDING | Q5: =IF(F5=0,0,MAX(0,ROUND(K5-M5,2))) -> 1000 | R5: =IF(F5=0,"NOT_APPLICABLE",IF(AND(M5>=K5,K5>0),"CLEARED",IF(M5>0,"PARTIAL","PENDING"))) -> PENDING | S5: =COUNTIF('Payment Lines'!$B$4:$B$60,B5) -> 0 | T5: Leave unpaid. Expect PENDING, TDS 1,000 pending.
A6: 2 | B6: =Invoices!A3 -> ALL-2026-002 | C6: TDS 10% | not due (in 25 days) | partial cash + TDS | D6: =Invoices!B3 -> Kaveri Tech Park LLP | E6: =Invoices!C3 -> Kaveri - Block 1 | F6: =IFERROR(INDEX(Customers!$F$4:$F$13,MATCH(TRIM(D6),Customers!$B$4:$B$13,0)),IFERROR(INDEX(Customers!$F$4:$F$13,MATCH(TRIM(D6),Customers!$C$4:$C$13,0)),0)) -> 10 | G6: =Invoices!E3 -> 46310 | H6: =$B$2-G6 -> -25 | I6: =IF(G6<$B$2,"OVERDUE","PENDING") -> PENDING | J6: =Invoices!F3 -> 100000 | K6: =ROUND(J6*F6/100,2) -> 10000 | L6: =SUMIFS('Payment Lines'!$C$4:$C$60,'Payment Lines'!$B$4:$B$60,B6) -> 27000 | M6: =SUMIFS('Payment Lines'!$D$4:$D$60,'Payment Lines'!$B$4:$B$60,B6) -> 3000 | N6: =ROUND(L6+SUMIFS('Payment Lines'!$D$4:$D$60,'Payment Lines'!$B$4:$B$60,B6,'Payment Lines'!$E$4:$E$60,"CURRENT"),2) -> 30000 | O6: =IF(U6="CANCEL",J6,ROUND(J6-N6,2)) -> 70000 | P6: =IF(U6="CANCEL","CANCELLED",IF(O6<=0,"PAID",IF(G6<$B$2,"OVERDUE",IF(N6>0,"PARTIAL","PENDING")))) -> PARTIAL | Q6: =IF(F6=0,0,MAX(0,ROUND(K6-M6,2))) -> 7000 | R6: =IF(F6=0,"NOT_APPLICABLE",IF(AND(M6>=K6,K6>0),"CLEARED",IF(M6>0,"PARTIAL","PENDING"))) -> PARTIAL | S6: =COUNTIF('Payment Lines'!$B$4:$B$60,B6) -> 1 | T6: Pay cash 27,000 + TDS 3,000 (P18): PARTIAL, TDS PARTIAL.
A7: 3 | B7: =Invoices!A4 -> ALL-2026-003 | C7: TDS 1.5% | not due (in 30 days) | nothing paid | D7: =Invoices!B4 -> Green Meadow School | E7: =Invoices!C4 -> Green Meadow - Main Campus | F7: =IFERROR(INDEX(Customers!$F$4:$F$13,MATCH(TRIM(D7),Customers!$B$4:$B$13,0)),IFERROR(INDEX(Customers!$F$4:$F$13,MATCH(TRIM(D7),Customers!$C$4:$C$13,0)),0)) -> 1.5 | G7: =Invoices!E4 -> 46315 | H7: =$B$2-G7 -> -30 | I7: =IF(G7<$B$2,"OVERDUE","PENDING") -> PENDING | J7: =Invoices!F4 -> 27500 | K7: =ROUND(J7*F7/100,2) -> 412.5 | L7: =SUMIFS('Payment Lines'!$C$4:$C$60,'Payment Lines'!$B$4:$B$60,B7) -> 0 | M7: =SUMIFS('Payment Lines'!$D$4:$D$60,'Payment Lines'!$B$4:$B$60,B7) -> 0 | N7: =ROUND(L7+SUMIFS('Payment Lines'!$D$4:$D$60,'Payment Lines'!$B$4:$B$60,B7,'Payment Lines'!$E$4:$E$60,"CURRENT"),2) -> 0 | O7: =IF(U7="CANCEL",J7,ROUND(J7-N7,2)) -> 27500 | P7: =IF(U7="CANCEL","CANCELLED",IF(O7<=0,"PAID",IF(G7<$B$2,"OVERDUE",IF(N7>0,"PARTIAL","PENDING")))) -> PENDING | Q7: =IF(F7=0,0,MAX(0,ROUND(K7-M7,2))) -> 412.5 | R7: =IF(F7=0,"NOT_APPLICABLE",IF(AND(M7>=K7,K7>0),"CLEARED",IF(M7>0,"PARTIAL","PENDING"))) -> PENDING | S7: =COUNTIF('Payment Lines'!$B$4:$B$60,B7) -> 0 | T7: Leave unpaid. Expect PENDING, TDS 412.50 pending.
A8: 4 | B8: =Invoices!A5 -> ALL-2026-004 | C8: No TDS customer | not due | nothing paid | D8: =Invoices!B5 -> Sunrise Apartments Owners Assn | E8: =Invoices!C5 -> Sunrise - Tower A | F8: =IFERROR(INDEX(Customers!$F$4:$F$13,MATCH(TRIM(D8),Customers!$B$4:$B$13,0)),IFERROR(INDEX(Customers!$F$4:$F$13,MATCH(TRIM(D8),Customers!$C$4:$C$13,0)),0)) -> 0 | G8: =Invoices!E5 -> 46300 | H8: =$B$2-G8 -> -15 | I8: =IF(G8<$B$2,"OVERDUE","PENDING") -> PENDING | J8: =Invoices!F5 -> 12500 | K8: =ROUND(J8*F8/100,2) -> 0 | L8: =SUMIFS('Payment Lines'!$C$4:$C$60,'Payment Lines'!$B$4:$B$60,B8) -> 0 | M8: =SUMIFS('Payment Lines'!$D$4:$D$60,'Payment Lines'!$B$4:$B$60,B8) -> 0 | N8: =ROUND(L8+SUMIFS('Payment Lines'!$D$4:$D$60,'Payment Lines'!$B$4:$B$60,B8,'Payment Lines'!$E$4:$E$60,"CURRENT"),2) -> 0 | O8: =IF(U8="CANCEL",J8,ROUND(J8-N8,2)) -> 12500 | P8: =IF(U8="CANCEL","CANCELLED",IF(O8<=0,"PAID",IF(G8<$B$2,"OVERDUE",IF(N8>0,"PARTIAL","PENDING")))) -> PENDING | Q8: =IF(F8=0,0,MAX(0,ROUND(K8-M8,2))) -> 0 | R8: =IF(F8=0,"NOT_APPLICABLE",IF(AND(M8>=K8,K8>0),"CLEARED",IF(M8>0,"PARTIAL","PENDING"))) -> NOT_APPLICABLE | S8: =COUNTIF('Payment Lines'!$B$4:$B$60,B8) -> 0 | T8: Leave unpaid. Expect PENDING, TDS not applicable.
A9: 5 | B9: =Invoices!A6 -> ALL-2026-005 | C9: No TDS customer | decimals | nothing paid | D9: =Invoices!B6 -> Café Zoë & Sons (Pvt) Ltd | E9: =Invoices!C6 -> Café Zoë - Main Outlet | F9: =IFERROR(INDEX(Customers!$F$4:$F$13,MATCH(TRIM(D9),Customers!$B$4:$B$13,0)),IFERROR(INDEX(Customers!$F$4:$F$13,MATCH(TRIM(D9),Customers!$C$4:$C$13,0)),0)) -> 0 | G9: =Invoices!E6 -> 46330 | H9: =$B$2-G9 -> -45 | I9: =IF(G9<$B$2,"OVERDUE","PENDING") -> PENDING | J9: =Invoices!F6 -> 8750.75 | K9: =ROUND(J9*F9/100,2) -> 0 | L9: =SUMIFS('Payment Lines'!$C$4:$C$60,'Payment Lines'!$B$4:$B$60,B9) -> 0 | M9: =SUMIFS('Payment Lines'!$D$4:$D$60,'Payment Lines'!$B$4:$B$60,B9) -> 0 | N9: =ROUND(L9+SUMIFS('Payment Lines'!$D$4:$D$60,'Payment Lines'!$B$4:$B$60,B9,'Payment Lines'!$E$4:$E$60,"CURRENT"),2) -> 0 | O9: =IF(U9="CANCEL",J9,ROUND(J9-N9,2)) -> 8750.75 | P9: =IF(U9="CANCEL","CANCELLED",IF(O9<=0,"PAID",IF(G9<$B$2,"OVERDUE",IF(N9>0,"PARTIAL","PENDING")))) -> PENDING | Q9: =IF(F9=0,0,MAX(0,ROUND(K9-M9,2))) -> 0 | R9: =IF(F9=0,"NOT_APPLICABLE",IF(AND(M9>=K9,K9>0),"CLEARED",IF(M9>0,"PARTIAL","PENDING"))) -> NOT_APPLICABLE | S9: =COUNTIF('Payment Lines'!$B$4:$B$60,B9) -> 0 | T9: Leave unpaid. Amount shows Rs 8,750.75.
A10: 6 | B10: =Invoices!A7 -> ALL-2026-006 | C10: TDS 2% | OVERDUE 110 days | nothing paid | D10: =Invoices!B7 -> Bluewave Hotels Pvt Ltd | E10: =Invoices!C7 -> Bluewave - Whitefield | F10: =IFERROR(INDEX(Customers!$F$4:$F$13,MATCH(TRIM(D10),Customers!$B$4:$B$13,0)),IFERROR(INDEX(Customers!$F$4:$F$13,MATCH(TRIM(D10),Customers!$C$4:$C$13,0)),0)) -> 2 | G10: =Invoices!E7 -> 46175 | H10: =$B$2-G10 -> 110 | I10: =IF(G10<$B$2,"OVERDUE","PENDING") -> OVERDUE | J10: =Invoices!F7 -> 80000 | K10: =ROUND(J10*F10/100,2) -> 1600 | L10: =SUMIFS('Payment Lines'!$C$4:$C$60,'Payment Lines'!$B$4:$B$60,B10) -> 0 | M10: =SUMIFS('Payment Lines'!$D$4:$D$60,'Payment Lines'!$B$4:$B$60,B10) -> 0 | N10: =ROUND(L10+SUMIFS('Payment Lines'!$D$4:$D$60,'Payment Lines'!$B$4:$B$60,B10,'Payment Lines'!$E$4:$E$60,"CURRENT"),2) -> 0 | O10: =IF(U10="CANCEL",J10,ROUND(J10-N10,2)) -> 80000 | P10: =IF(U10="CANCEL","CANCELLED",IF(O10<=0,"PAID",IF(G10<$B$2,"OVERDUE",IF(N10>0,"PARTIAL","PENDING")))) -> OVERDUE | Q10: =IF(F10=0,0,MAX(0,ROUND(K10-M10,2))) -> 1600 | R10: =IF(F10=0,"NOT_APPLICABLE",IF(AND(M10>=K10,K10>0),"CLEARED",IF(M10>0,"PARTIAL","PENDING"))) -> PENDING | S10: =COUNTIF('Payment Lines'!$B$4:$B$60,B10) -> 0 | T10: Leave unpaid. Expect OVERDUE, 110 days late.
A11: 7 | B11: =Invoices!A8 -> ALL-2026-007 | C11: TDS 10% | OVERDUE 60 days | nothing paid | D11: =Invoices!B8 -> Kaveri Tech Park LLP | E11: =Invoices!C8 -> Kaveri - Block 2 | F11: =IFERROR(INDEX(Customers!$F$4:$F$13,MATCH(TRIM(D11),Customers!$B$4:$B$13,0)),IFERROR(INDEX(Customers!$F$4:$F$13,MATCH(TRIM(D11),Customers!$C$4:$C$13,0)),0)) -> 10 | G11: =Invoices!E8 -> 46225 | H11: =$B$2-G11 -> 60 | I11: =IF(G11<$B$2,"OVERDUE","PENDING") -> OVERDUE | J11: =Invoices!F8 -> 150000 | K11: =ROUND(J11*F11/100,2) -> 15000 | L11: =SUMIFS('Payment Lines'!$C$4:$C$60,'Payment Lines'!$B$4:$B$60,B11) -> 0 | M11: =SUMIFS('Payment Lines'!$D$4:$D$60,'Payment Lines'!$B$4:$B$60,B11) -> 0 | N11: =ROUND(L11+SUMIFS('Payment Lines'!$D$4:$D$60,'Payment Lines'!$B$4:$B$60,B11,'Payment Lines'!$E$4:$E$60,"CURRENT"),2) -> 0 | O11: =IF(U11="CANCEL",J11,ROUND(J11-N11,2)) -> 150000 | P11: =IF(U11="CANCEL","CANCELLED",IF(O11<=0,"PAID",IF(G11<$B$2,"OVERDUE",IF(N11>0,"PARTIAL","PENDING")))) -> OVERDUE | Q11: =IF(F11=0,0,MAX(0,ROUND(K11-M11,2))) -> 15000 | R11: =IF(F11=0,"NOT_APPLICABLE",IF(AND(M11>=K11,K11>0),"CLEARED",IF(M11>0,"PARTIAL","PENDING"))) -> PENDING | S11: =COUNTIF('Payment Lines'!$B$4:$B$60,B11) -> 0 | T11: Leave unpaid. Expect OVERDUE, TDS 15,000 pending.
A12: 8 | B12: =Invoices!A9 -> ALL-2026-008 | C12: TDS 2% | OVERDUE 30 days | nothing paid | D12: =Invoices!B9 -> Lotus Diagnostics Centre | E12: =Invoices!C9 -> Lotus - Jayanagar Lab | F12: =IFERROR(INDEX(Customers!$F$4:$F$13,MATCH(TRIM(D12),Customers!$B$4:$B$13,0)),IFERROR(INDEX(Customers!$F$4:$F$13,MATCH(TRIM(D12),Customers!$C$4:$C$13,0)),0)) -> 2 | G12: =Invoices!E9 -> 46255 | H12: =$B$2-G12 -> 30 | I12: =IF(G12<$B$2,"OVERDUE","PENDING") -> OVERDUE | J12: =Invoices!F9 -> 45000 | K12: =ROUND(J12*F12/100,2) -> 900 | L12: =SUMIFS('Payment Lines'!$C$4:$C$60,'Payment Lines'!$B$4:$B$60,B12) -> 0 | M12: =SUMIFS('Payment Lines'!$D$4:$D$60,'Payment Lines'!$B$4:$B$60,B12) -> 0 | N12: =ROUND(L12+SUMIFS('Payment Lines'!$D$4:$D$60,'Payment Lines'!$B$4:$B$60,B12,'Payment Lines'!$E$4:$E$60,"CURRENT"),2) -> 0 | O12: =IF(U12="CANCEL",J12,ROUND(J12-N12,2)) -> 45000 | P12: =IF(U12="CANCEL","CANCELLED",IF(O12<=0,"PAID",IF(G12<$B$2,"OVERDUE",IF(N12>0,"PARTIAL","PENDING")))) -> OVERDUE | Q12: =IF(F12=0,0,MAX(0,ROUND(K12-M12,2))) -> 900 | R12: =IF(F12=0,"NOT_APPLICABLE",IF(AND(M12>=K12,K12>0),"CLEARED",IF(M12>0,"PARTIAL","PENDING"))) -> PENDING | S12: =COUNTIF('Payment Lines'!$B$4:$B$60,B12) -> 0 | T12: Leave unpaid. Expect OVERDUE.
A13: 9 | B13: =Invoices!A10 -> ALL-2026-009 | C13: TDS 1.5% | OVERDUE 10 days | nothing paid | D13: =Invoices!B10 -> Green Meadow School | E13: =Invoices!C10 -> Green Meadow - Annex | F13: =IFERROR(INDEX(Customers!$F$4:$F$13,MATCH(TRIM(D13),Customers!$B$4:$B$13,0)),IFERROR(INDEX(Customers!$F$4:$F$13,MATCH(TRIM(D13),Customers!$C$4:$C$13,0)),0)) -> 1.5 | G13: =Invoices!E10 -> 46275 | H13: =$B$2-G13 -> 10 | I13: =IF(G13<$B$2,"OVERDUE","PENDING") -> OVERDUE | J13: =Invoices!F10 -> 33340 | K13: =ROUND(J13*F13/100,2) -> 500.1 | L13: =SUMIFS('Payment Lines'!$C$4:$C$60,'Payment Lines'!$B$4:$B$60,B13) -> 0 | M13: =SUMIFS('Payment Lines'!$D$4:$D$60,'Payment Lines'!$B$4:$B$60,B13) -> 0 | N13: =ROUND(L13+SUMIFS('Payment Lines'!$D$4:$D$60,'Payment Lines'!$B$4:$B$60,B13,'Payment Lines'!$E$4:$E$60,"CURRENT"),2) -> 0 | O13: =IF(U13="CANCEL",J13,ROUND(J13-N13,2)) -> 33340 | P13: =IF(U13="CANCEL","CANCELLED",IF(O13<=0,"PAID",IF(G13<$B$2,"OVERDUE",IF(N13>0,"PARTIAL","PENDING")))) -> OVERDUE | Q13: =IF(F13=0,0,MAX(0,ROUND(K13-M13,2))) -> 500.1 | R13: =IF(F13=0,"NOT_APPLICABLE",IF(AND(M13>=K13,K13>0),"CLEARED",IF(M13>0,"PARTIAL","PENDING"))) -> PENDING | S13: =COUNTIF('Payment Lines'!$B$4:$B$60,B13) -> 0 | T13: Leave unpaid. Expect OVERDUE, TDS 500.10.
A14: 10 | B14: =Invoices!A11 -> ALL-2026-010 | C14: No TDS customer | OVERDUE by 1 day | D14: =Invoices!B11 -> Sunrise Apartments Owners Assn | E14: =Invoices!C11 -> Sunrise - Tower B | F14: =IFERROR(INDEX(Customers!$F$4:$F$13,MATCH(TRIM(D14),Customers!$B$4:$B$13,0)),IFERROR(INDEX(Customers!$F$4:$F$13,MATCH(TRIM(D14),Customers!$C$4:$C$13,0)),0)) -> 0 | G14: =Invoices!E11 -> 46284 | H14: =$B$2-G14 -> 1 | I14: =IF(G14<$B$2,"OVERDUE","PENDING") -> OVERDUE | J14: =Invoices!F11 -> 18000 | K14: =ROUND(J14*F14/100,2) -> 0 | L14: =SUMIFS('Payment Lines'!$C$4:$C$60,'Payment Lines'!$B$4:$B$60,B14) -> 0 | M14: =SUMIFS('Payment Lines'!$D$4:$D$60,'Payment Lines'!$B$4:$B$60,B14) -> 0 | N14: =ROUND(L14+SUMIFS('Payment Lines'!$D$4:$D$60,'Payment Lines'!$B$4:$B$60,B14,'Payment Lines'!$E$4:$E$60,"CURRENT"),2) -> 0 | O14: =IF(U14="CANCEL",J14,ROUND(J14-N14,2)) -> 18000 | P14: =IF(U14="CANCEL","CANCELLED",IF(O14<=0,"PAID",IF(G14<$B$2,"OVERDUE",IF(N14>0,"PARTIAL","PENDING")))) -> OVERDUE | Q14: =IF(F14=0,0,MAX(0,ROUND(K14-M14,2))) -> 0 | R14: =IF(F14=0,"NOT_APPLICABLE",IF(AND(M14>=K14,K14>0),"CLEARED",IF(M14>0,"PARTIAL","PENDING"))) -> NOT_APPLICABLE | S14: =COUNTIF('Payment Lines'!$B$4:$B$60,B14) -> 0 | T14: Leave unpaid. Expect OVERDUE (1 day late).
A15: 11 | B15: =Invoices!A12 -> ALL-2026-011 | C15: No TDS customer | OVERDUE 45 days | D15: =Invoices!B12 -> Café Zoë & Sons (Pvt) Ltd | E15: =Invoices!C12 -> Café Zoë - Kiosk 2 | F15: =IFERROR(INDEX(Customers!$F$4:$F$13,MATCH(TRIM(D15),Customers!$B$4:$B$13,0)),IFERROR(INDEX(Customers!$F$4:$F$13,MATCH(TRIM(D15),Customers!$C$4:$C$13,0)),0)) -> 0 | G15: =Invoices!E12 -> 46240 | H15: =$B$2-G15 -> 45 | I15: =IF(G15<$B$2,"OVERDUE","PENDING") -> OVERDUE | J15: =Invoices!F12 -> 6400 | K15: =ROUND(J15*F15/100,2) -> 0 | L15: =SUMIFS('Payment Lines'!$C$4:$C$60,'Payment Lines'!$B$4:$B$60,B15) -> 0 | M15: =SUMIFS('Payment Lines'!$D$4:$D$60,'Payment Lines'!$B$4:$B$60,B15) -> 0 | N15: =ROUND(L15+SUMIFS('Payment Lines'!$D$4:$D$60,'Payment Lines'!$B$4:$B$60,B15,'Payment Lines'!$E$4:$E$60,"CURRENT"),2) -> 0 | O15: =IF(U15="CANCEL",J15,ROUND(J15-N15,2)) -> 6400 | P15: =IF(U15="CANCEL","CANCELLED",IF(O15<=0,"PAID",IF(G15<$B$2,"OVERDUE",IF(N15>0,"PARTIAL","PENDING")))) -> OVERDUE | Q15: =IF(F15=0,0,MAX(0,ROUND(K15-M15,2))) -> 0 | R15: =IF(F15=0,"NOT_APPLICABLE",IF(AND(M15>=K15,K15>0),"CLEARED",IF(M15>0,"PARTIAL","PENDING"))) -> NOT_APPLICABLE | S15: =COUNTIF('Payment Lines'!$B$4:$B$60,B15) -> 0 | T15: Leave unpaid. Expect OVERDUE.
A16: 12 | B16: =Invoices!A13 -> ALL-2026-012 | C16: Due TODAY | TDS 2% | D16: =Invoices!B13 -> Lotus Diagnostics Centre | E16: =Invoices!C13 -> Lotus - HSR Lab | F16: =IFERROR(INDEX(Customers!$F$4:$F$13,MATCH(TRIM(D16),Customers!$B$4:$B$13,0)),IFERROR(INDEX(Customers!$F$4:$F$13,MATCH(TRIM(D16),Customers!$C$4:$C$13,0)),0)) -> 2 | G16: =Invoices!E13 -> 46285 | H16: =$B$2-G16 -> 0 | I16: =IF(G16<$B$2,"OVERDUE","PENDING") -> PENDING | J16: =Invoices!F13 -> 27500 | K16: =ROUND(J16*F16/100,2) -> 550 | L16: =SUMIFS('Payment Lines'!$C$4:$C$60,'Payment Lines'!$B$4:$B$60,B16) -> 0 | M16: =SUMIFS('Payment Lines'!$D$4:$D$60,'Payment Lines'!$B$4:$B$60,B16) -> 0 | N16: =ROUND(L16+SUMIFS('Payment Lines'!$D$4:$D$60,'Payment Lines'!$B$4:$B$60,B16,'Payment Lines'!$E$4:$E$60,"CURRENT"),2) -> 0 | O16: =IF(U16="CANCEL",J16,ROUND(J16-N16,2)) -> 27500 | P16: =IF(U16="CANCEL","CANCELLED",IF(O16<=0,"PAID",IF(G16<$B$2,"OVERDUE",IF(N16>0,"PARTIAL","PENDING")))) -> PENDING | Q16: =IF(F16=0,0,MAX(0,ROUND(K16-M16,2))) -> 550 | R16: =IF(F16=0,"NOT_APPLICABLE",IF(AND(M16>=K16,K16>0),"CLEARED",IF(M16>0,"PARTIAL","PENDING"))) -> PENDING | S16: =COUNTIF('Payment Lines'!$B$4:$B$60,B16) -> 0 | T16: Leave unpaid. Expect PENDING (not overdue), counts under Due Today.
... A35: 31 | B35: =Invoices!A32 -> ALL-2026-031 | C35: PAY: advance - customer sends more cash than the invoice | D35: =Invoices!B32 -> Lotus Diagnostics Centre | E35: =Invoices!C32 -> Lotus - Jayanagar Lab | F35: =IFERROR(INDEX(Customers!$F$4:$F$13,MATCH(TRIM(D35),Customers!$B$4:$B$13,0)),IFERROR(INDEX(Customers!$F$4:$F$13,MATCH(TRIM(D35),Customers!$C$4:$C$13,0)),0)) -> 2 | G35: =Invoices!E32 -> 46290 | H35: =$B$2-G35 -> -5 | I35: =IF(G35<$B$2,"OVERDUE","PENDING") -> PENDING | J35: =Invoices!F32 -> 15000 | K35: =ROUND(J35*F35/100,2) -> 300 | L35: =SUMIFS('Payment Lines'!$C$4:$C$60,'Payment Lines'!$B$4:$B$60,B35) -> 14700 | M35: =SUMIFS('Payment Lines'!$D$4:$D$60,'Payment Lines'!$B$4:$B$60,B35) -> 300 | N35: =ROUND(L35+SUMIFS('Payment Lines'!$D$4:$D$60,'Payment Lines'!$B$4:$B$60,B35,'Payment Lines'!$E$4:$E$60,"CURRENT"),2) -> 15000 | O35: =IF(U35="CANCEL",J35,ROUND(J35-N35,2)) -> 0 | P35: =IF(U35="CANCEL","CANCELLED",IF(O35<=0,"PAID",IF(G35<$B$2,"OVERDUE",IF(N35>0,"PARTIAL","PENDING")))) -> PAID | Q35: =IF(F35=0,0,MAX(0,ROUND(K35-M35,2))) -> 0 | R35: =IF(F35=0,"NOT_APPLICABLE",IF(AND(M35>=K35,K35>0),"CLEARED",IF(M35>0,"PARTIAL","PENDING"))) -> CLEARED | S35: =COUNTIF('Payment Lines'!$B$4:$B$60,B35) -> 1 | T35: P10: type cash 20,000, allocate 14,700 + TDS 300. Payment shows 5,300 unallocated.
A36: 32 | B36: =Invoices!A33 -> ALL-2026-032 | C36: CANCEL: cancel an unpaid invoice | D36: =Invoices!B33 -> Café Zoë & Sons (Pvt) Ltd | E36: =Invoices!C33 -> Café Zoë - Kiosk 2 | F36: =IFERROR(INDEX(Customers!$F$4:$F$13,MATCH(TRIM(D36),Customers!$B$4:$B$13,0)),IFERROR(INDEX(Customers!$F$4:$F$13,MATCH(TRIM(D36),Customers!$C$4:$C$13,0)),0)) -> 0 | G36: =Invoices!E33 -> 46305 | H36: =$B$2-G36 -> -20 | I36: =IF(G36<$B$2,"OVERDUE","PENDING") -> PENDING | J36: =Invoices!F33 -> 5000 | K36: =ROUND(J36*F36/100,2) -> 0 | L36: =SUMIFS('Payment Lines'!$C$4:$C$60,'Payment Lines'!$B$4:$B$60,B36) -> 0 | M36: =SUMIFS('Payment Lines'!$D$4:$D$60,'Payment Lines'!$B$4:$B$60,B36) -> 0 | N36: =ROUND(L36+SUMIFS('Payment Lines'!$D$4:$D$60,'Payment Lines'!$B$4:$B$60,B36,'Payment Lines'!$E$4:$E$60,"CURRENT"),2) -> 0 | O36: =IF(U36="CANCEL",J36,ROUND(J36-N36,2)) -> 5000 | P36: =IF(U36="CANCEL","CANCELLED",IF(O36<=0,"PAID",IF(G36<$B$2,"OVERDUE",IF(N36>0,"PARTIAL","PENDING")))) -> CANCELLED | Q36: =IF(F36=0,0,MAX(0,ROUND(K36-M36,2))) -> 0 | R36: =IF(F36=0,"NOT_APPLICABLE",IF(AND(M36>=K36,K36>0),"CLEARED",IF(M36>0,"PARTIAL","PENDING"))) -> NOT_APPLICABLE | S36: =COUNTIF('Payment Lines'!$B$4:$B$60,B36) -> 0 | T36: Cancel this invoice. Expect CANCELLED and excluded from totals. | U36: CANCEL
A37: 33 | B37: =Invoices!A34 -> ALL-2026-033 | C37: PAY then TRY to cancel (must be blocked) | D37: =Invoices!B34 -> Café Zoë & Sons (Pvt) Ltd | E37: =Invoices!C34 -> Café Zoë - Main Outlet | F37: =IFERROR(INDEX(Customers!$F$4:$F$13,MATCH(TRIM(D37),Customers!$B$4:$B$13,0)),IFERROR(INDEX(Customers!$F$4:$F$13,MATCH(TRIM(D37),Customers!$C$4:$C$13,0)),0)) -> 0 | G37: =Invoices!E34 -> 46305 | H37: =$B$2-G37 -> -20 | I37: =IF(G37<$B$2,"OVERDUE","PENDING") -> PENDING | J37: =Invoices!F34 -> 7000 | K37: =ROUND(J37*F37/100,2) -> 0 | L37: =SUMIFS('Payment Lines'!$C$4:$C$60,'Payment Lines'!$B$4:$B$60,B37) -> 7000 | M37: =SUMIFS('Payment Lines'!$D$4:$D$60,'Payment Lines'!$B$4:$B$60,B37) -> 0 | N37: =ROUND(L37+SUMIFS('Payment Lines'!$D$4:$D$60,'Payment Lines'!$B$4:$B$60,B37,'Payment Lines'!$E$4:$E$60,"CURRENT"),2) -> 7000 | O37: =IF(U37="CANCEL",J37,ROUND(J37-N37,2)) -> 0 | P37: =IF(U37="CANCEL","CANCELLED",IF(O37<=0,"PAID",IF(G37<$B$2,"OVERDUE",IF(N37>0,"PARTIAL","PENDING")))) -> PAID | Q37: =IF(F37=0,0,MAX(0,ROUND(K37-M37,2))) -> 0 | R37: =IF(F37=0,"NOT_APPLICABLE",IF(AND(M37>=K37,K37>0),"CLEARED",IF(M37>0,"PARTIAL","PENDING"))) -> NOT_APPLICABLE | S37: =COUNTIF('Payment Lines'!$B$4:$B$60,B37) -> 1 | T37: P11 cash 7,000 (PAID). Then try Cancel: 'Cannot cancel an invoice that already has payments'.
A38: 34 | B38: =Invoices!A35 -> ALL-2026-034 | C38: PAY: rounding - TDS 666.66 | D38: =Invoices!B35 -> Bluewave Hotels Pvt Ltd | E38: =Invoices!C35 -> Bluewave - Indiranagar | F38: =IFERROR(INDEX(Customers!$F$4:$F$13,MATCH(TRIM(D38),Customers!$B$4:$B$13,0)),IFERROR(INDEX(Customers!$F$4:$F$13,MATCH(TRIM(D38),Customers!$C$4:$C$13,0)),0)) -> 2 | G38: =Invoices!E35 -> 46300 | H38: =$B$2-G38 -> -15 | I38: =IF(G38<$B$2,"OVERDUE","PENDING") -> PENDING | J38: =Invoices!F35 -> 33333 | K38: =ROUND(J38*F38/100,2) -> 666.66 | L38: =SUMIFS('Payment Lines'!$C$4:$C$60,'Payment Lines'!$B$4:$B$60,B38) -> 32666.34 | M38: =SUMIFS('Payment Lines'!$D$4:$D$60,'Payment Lines'!$B$4:$B$60,B38) -> 666.66 | N38: =ROUND(L38+SUMIFS('Payment Lines'!$D$4:$D$60,'Payment Lines'!$B$4:$B$60,B38,'Payment Lines'!$E$4:$E$60,"CURRENT"),2) -> 33333 | O38: =IF(U38="CANCEL",J38,ROUND(J38-N38,2)) -> 0 | P38: =IF(U38="CANCEL","CANCELLED",IF(O38<=0,"PAID",IF(G38<$B$2,"OVERDUE",IF(N38>0,"PARTIAL","PENDING")))) -> PAID | Q38: =IF(F38=0,0,MAX(0,ROUND(K38-M38,2))) -> 0 | R38: =IF(F38=0,"NOT_APPLICABLE",IF(AND(M38>=K38,K38>0),"CLEARED",IF(M38>0,"PARTIAL","PENDING"))) -> CLEARED | S38: =COUNTIF('Payment Lines'!$B$4:$B$60,B38) -> 1 | T38: P12 cash 32,666.34 + TDS 666.66. Expect PAID.
A39: 35 | B39: =Invoices!A36 -> ALL-2026-035 | C39: PAY: rounding - TDS 4,567.89 | D39: =Invoices!B36 -> Kaveri Tech Park LLP | E39: =Invoices!C36 -> Kaveri - Food Court | F39: =IFERROR(INDEX(Customers!$F$4:$F$13,MATCH(TRIM(D39),Customers!$B$4:$B$13,0)),IFERROR(INDEX(Customers!$F$4:$F$13,MATCH(TRIM(D39),Customers!$C$4:$C$13,0)),0)) -> 10 | G39: =Invoices!E36 -> 46300 | H39: =$B$2-G39 -> -15 | I39: =IF(G39<$B$2,"OVERDUE","PENDING") -> PENDING | J39: =Invoices!F36 -> 45678.9 | K39: =ROUND(J39*F39/100,2) -> 4567.89 | L39: =SUMIFS('Payment Lines'!$C$4:$C$60,'Payment Lines'!$B$4:$B$60,B39) -> 41111.01 | M39: =SUMIFS('Payment Lines'!$D$4:$D$60,'Payment Lines'!$B$4:$B$60,B39) -> 4567.89 | N39: =ROUND(L39+SUMIFS('Payment Lines'!$D$4:$D$60,'Payment Lines'!$B$4:$B$60,B39,'Payment Lines'!$E$4:$E$60,"CURRENT"),2) -> 45678.9 | O39: =IF(U39="CANCEL",J39,ROUND(J39-N39,2)) -> 0 | P39: =IF(U39="CANCEL","CANCELLED",IF(O39<=0,"PAID",IF(G39<$B$2,"OVERDUE",IF(N39>0,"PARTIAL","PENDING")))) -> PAID | Q39: =IF(F39=0,0,MAX(0,ROUND(K39-M39,2))) -> 0 | R39: =IF(F39=0,"NOT_APPLICABLE",IF(AND(M39>=K39,K39>0),"CLEARED",IF(M39>0,"PARTIAL","PENDING"))) -> CLEARED | S39: =COUNTIF('Payment Lines'!$B$4:$B$60,B39) -> 1 | T39: P13 cash 41,111.01 + TDS 4,567.89. Expect PAID.
A40: 36 | B40: =Invoices!A37 -> ALL-2026-036 | C40: PAY: rounding - TDS 24.69 | D40: =Invoices!B37 -> Lotus Diagnostics Centre | E40: =Invoices!C37 -> Lotus - HSR Lab | F40: =IFERROR(INDEX(Customers!$F$4:$F$13,MATCH(TRIM(D40),Customers!$B$4:$B$13,0)),IFERROR(INDEX(Customers!$F$4:$F$13,MATCH(TRIM(D40),Customers!$C$4:$C$13,0)),0)) -> 2 | G40: =Invoices!E37 -> 46300 | H40: =$B$2-G40 -> -15 | I40: =IF(G40<$B$2,"OVERDUE","PENDING") -> PENDING | J40: =Invoices!F37 -> 1234.56 | K40: =ROUND(J40*F40/100,2) -> 24.69 | L40: =SUMIFS('Payment Lines'!$C$4:$C$60,'Payment Lines'!$B$4:$B$60,B40) -> 1209.87 | M40: =SUMIFS('Payment Lines'!$D$4:$D$60,'Payment Lines'!$B$4:$B$60,B40) -> 24.69 | N40: =ROUND(L40+SUMIFS('Payment Lines'!$D$4:$D$60,'Payment Lines'!$B$4:$B$60,B40,'Payment Lines'!$E$4:$E$60,"CURRENT"),2) -> 1234.56 | O40: =IF(U40="CANCEL",J40,ROUND(J40-N40,2)) -> 0 | P40: =IF(U40="CANCEL","CANCELLED",IF(O40<=0,"PAID",IF(G40<$B$2,"OVERDUE",IF(N40>0,"PARTIAL","PENDING")))) -> PAID | Q40: =IF(F40=0,0,MAX(0,ROUND(K40-M40,2))) -> 0 | R40: =IF(F40=0,"NOT_APPLICABLE",IF(AND(M40>=K40,K40>0),"CLEARED",IF(M40>0,"PARTIAL","PENDING"))) -> CLEARED | S40: =COUNTIF('Payment Lines'!$B$4:$B$60,B40) -> 1 | T40: P14 cash 1,209.87 + TDS 24.69. Expect PAID.
A41: 37 | B41: =Invoices!A38 -> ALL-2026-037 | C41: PAY: rounding - TDS 131.26 | D41: =Invoices!B38 -> Green Meadow School | E41: =Invoices!C38 -> Green Meadow - Main Campus | F41: =IFERROR(INDEX(Customers!$F$4:$F$13,MATCH(TRIM(D41),Customers!$B$4:$B$13,0)),IFERROR(INDEX(Customers!$F$4:$F$13,MATCH(TRIM(D41),Customers!$C$4:$C$13,0)),0)) -> 1.5 | G41: =Invoices!E38 -> 46300 | H41: =$B$2-G41 -> -15 | I41: =IF(G41<$B$2,"OVERDUE","PENDING") -> PENDING | J41: =Invoices!F38 -> 8750.75 | K41: =ROUND(J41*F41/100,2) -> 131.26 | L41: =SUMIFS('Payment Lines'!$C$4:$C$60,'Payment Lines'!$B$4:$B$60,B41) -> 8619.49 | M41: =SUMIFS('Payment Lines'!$D$4:$D$60,'Payment Lines'!$B$4:$B$60,B41) -> 131.26 | N41: =ROUND(L41+SUMIFS('Payment Lines'!$D$4:$D$60,'Payment Lines'!$B$4:$B$60,B41,'Payment Lines'!$E$4:$E$60,"CURRENT"),2) -> 8750.75 | O41: =IF(U41="CANCEL",J41,ROUND(J41-N41,2)) -> 0 | P41: =IF(U41="CANCEL","CANCELLED",IF(O41<=0,"PAID",IF(G41<$B$2,"OVERDUE",IF(N41>0,"PARTIAL","PENDING")))) -> PAID | Q41: =IF(F41=0,0,MAX(0,ROUND(K41-M41,2))) -> 0 | R41: =IF(F41=0,"NOT_APPLICABLE",IF(AND(M41>=K41,K41>0),"CLEARED",IF(M41>0,"PARTIAL","PENDING"))) -> CLEARED | S41: =COUNTIF('Payment Lines'!$B$4:$B$60,B41) -> 1 | T41: P15 cash 8,619.49 + TDS 131.26. Expect PAID.
A42: 38 | B42: =Invoices!A39 -> ALL-2026-038 | C42: PAY: smallest amount | D42: =Invoices!B39 -> Café Zoë & Sons (Pvt) Ltd | E42: =Invoices!C39 -> Café Zoë - Main Outlet | F42: =IFERROR(INDEX(Customers!$F$4:$F$13,MATCH(TRIM(D42),Customers!$B$4:$B$13,0)),IFERROR(INDEX(Customers!$F$4:$F$13,MATCH(TRIM(D42),Customers!$C$4:$C$13,0)),0)) -> 0 | G42: =Invoices!E39 -> 46300 | H42: =$B$2-G42 -> -15 | I42: =IF(G42<$B$2,"OVERDUE","PENDING") -> PENDING | J42: =Invoices!F39 -> 0.01 | K42: =ROUND(J42*F42/100,2) -> 0 | L42: =SUMIFS('Payment Lines'!$C$4:$C$60,'Payment Lines'!$B$4:$B$60,B42) -> 0.01 | M42: =SUMIFS('Payment Lines'!$D$4:$D$60,'Payment Lines'!$B$4:$B$60,B42) -> 0 | N42: =ROUND(L42+SUMIFS('Payment Lines'!$D$4:$D$60,'Payment Lines'!$B$4:$B$60,B42,'Payment Lines'!$E$4:$E$60,"CURRENT"),2) -> 0.01 | O42: =IF(U42="CANCEL",J42,ROUND(J42-N42,2)) -> 0 | P42: =IF(U42="CANCEL","CANCELLED",IF(O42<=0,"PAID",IF(G42<$B$2,"OVERDUE",IF(N42>0,"PARTIAL","PENDING")))) -> PAID | Q42: =IF(F42=0,0,MAX(0,ROUND(K42-M42,2))) -> 0 | R42: =IF(F42=0,"NOT_APPLICABLE",IF(AND(M42>=K42,K42>0),"CLEARED",IF(M42>0,"PARTIAL","PENDING"))) -> NOT_APPLICABLE | S42: =COUNTIF('Payment Lines'!$B$4:$B$60,B42) -> 1 | T42: P16 cash 0.01. Expect PAID.
A43: 39 | B43: =Invoices!A40 -> ALL-2026-039 | C43: Large amount | TDS 10% = 999,999.95 | D43: =Invoices!B40 -> Kaveri Tech Park LLP | E43: =Invoices!C40 -> Kaveri - Block 2 | F43: =IFERROR(INDEX(Customers!$F$4:$F$13,MATCH(TRIM(D43),Customers!$B$4:$B$13,0)),IFERROR(INDEX(Customers!$F$4:$F$13,MATCH(TRIM(D43),Customers!$C$4:$C$13,0)),0)) -> 10 | G43: =Invoices!E40 -> 46345 | H43: =$B$2-G43 -> -60 | I43: =IF(G43<$B$2,"OVERDUE","PENDING") -> PENDING | J43: =Invoices!F40 -> 9999999.5 | K43: =ROUND(J43*F43/100,2) -> 999999.95 | L43: =SUMIFS('Payment Lines'!$C$4:$C$60,'Payment Lines'!$B$4:$B$60,B43) -> 0 | M43: =SUMIFS('Payment Lines'!$D$4:$D$60,'Payment Lines'!$B$4:$B$60,B43) -> 0 | N43: =ROUND(L43+SUMIFS('Payment Lines'!$D$4:$D$60,'Payment Lines'!$B$4:$B$60,B43,'Payment Lines'!$E$4:$E$60,"CURRENT"),2) -> 0 | O43: =IF(U43="CANCEL",J43,ROUND(J43-N43,2)) -> 9999999.5 | P43: =IF(U43="CANCEL","CANCELLED",IF(O43<=0,"PAID",IF(G43<$B$2,"OVERDUE",IF(N43>0,"PARTIAL","PENDING")))) -> PENDING | Q43: =IF(F43=0,0,MAX(0,ROUND(K43-M43,2))) -> 999999.95 | R43: =IF(F43=0,"NOT_APPLICABLE",IF(AND(M43>=K43,K43>0),"CLEARED",IF(M43>0,"PARTIAL","PENDING"))) -> PENDING | S43: =COUNTIF('Payment Lines'!$B$4:$B$60,B43) -> 0 | T43: Leave unpaid. Check big numbers display correctly.
A44: 40 | B44: =Invoices!A41 -> ALL-2026-040 | C44: Very old invoice, OVERDUE 200 days | D44: =Invoices!B41 -> Sunrise Apartments Owners Assn | E44: =Invoices!C41 -> Sunrise - Clubhouse | F44: =IFERROR(INDEX(Customers!$F$4:$F$13,MATCH(TRIM(D44),Customers!$B$4:$B$13,0)),IFERROR(INDEX(Customers!$F$4:$F$13,MATCH(TRIM(D44),Customers!$C$4:$C$13,0)),0)) -> 0 | G44: =Invoices!E41 -> 46085 | H44: =$B$2-G44 -> 200 | I44: =IF(G44<$B$2,"OVERDUE","PENDING") -> OVERDUE | J44: =Invoices!F41 -> 15000 | K44: =ROUND(J44*F44/100,2) -> 0 | L44: =SUMIFS('Payment Lines'!$C$4:$C$60,'Payment Lines'!$B$4:$B$60,B44) -> 0 | M44: =SUMIFS('Payment Lines'!$D$4:$D$60,'Payment Lines'!$B$4:$B$60,B44) -> 0 | N44: =ROUND(L44+SUMIFS('Payment Lines'!$D$4:$D$60,'Payment Lines'!$B$4:$B$60,B44,'Payment Lines'!$E$4:$E$60,"CURRENT"),2) -> 0 | O44: =IF(U44="CANCEL",J44,ROUND(J44-N44,2)) -> 15000 | P44: =IF(U44="CANCEL","CANCELLED",IF(O44<=0,"PAID",IF(G44<$B$2,"OVERDUE",IF(N44>0,"PARTIAL","PENDING")))) -> OVERDUE | Q44: =IF(F44=0,0,MAX(0,ROUND(K44-M44,2))) -> 0 | R44: =IF(F44=0,"NOT_APPLICABLE",IF(AND(M44>=K44,K44>0),"CLEARED",IF(M44>0,"PARTIAL","PENDING"))) -> NOT_APPLICABLE | S44: =COUNTIF('Payment Lines'!$B$4:$B$60,B44) -> 0 | T44: Leave unpaid. Expect OVERDUE, oldest due.
A45: 41 | B45: =Invoices!A42 -> ALL-2026-041 | C45: Customer typed as CODE (BWH01) | TDS 2% | D45: =Invoices!B42 -> BWH01 | E45: =Invoices!C42 -> Bluewave - Indiranagar | F45: =IFERROR(INDEX(Customers!$F$4:$F$13,MATCH(TRIM(D45),Customers!$B$4:$B$13,0)),IFERROR(INDEX(Customers!$F$4:$F$13,MATCH(TRIM(D45),Customers!$C$4:$C$13,0)),0)) -> 2 | G45: =Invoices!E42 -> 46303 | H45: =$B$2-G45 -> -18 | I45: =IF(G45<$B$2,"OVERDUE","PENDING") -> PENDING | J45: =Invoices!F42 -> 11000 | K45: =ROUND(J45*F45/100,2) -> 220 | L45: =SUMIFS('Payment Lines'!$C$4:$C$60,'Payment Lines'!$B$4:$B$60,B45) -> 0 | M45: =SUMIFS('Payment Lines'!$D$4:$D$60,'Payment Lines'!$B$4:$B$60,B45) -> 0 | N45: =ROUND(L45+SUMIFS('Payment Lines'!$D$4:$D$60,'Payment Lines'!$B$4:$B$60,B45,'Payment Lines'!$E$4:$E$60,"CURRENT"),2) -> 0 | O45: =IF(U45="CANCEL",J45,ROUND(J45-N45,2)) -> 11000 | P45: =IF(U45="CANCEL","CANCELLED",IF(O45<=0,"PAID",IF(G45<$B$2,"OVERDUE",IF(N45>0,"PARTIAL","PENDING")))) -> PENDING | Q45: =IF(F45=0,0,MAX(0,ROUND(K45-M45,2))) -> 220 | R45: =IF(F45=0,"NOT_APPLICABLE",IF(AND(M45>=K45,K45>0),"CLEARED",IF(M45>0,"PARTIAL","PENDING"))) -> PENDING | S45: =COUNTIF('Payment Lines'!$B$4:$B$60,B45) -> 0 | T45: Leave unpaid. Must import and show Bluewave, TDS 220.
A46: 42 | B46: =Invoices!A43 -> ALL-2026-042 | C46: Customer in capitals with spaces, site in lower case | D46: =Invoices!B43 -> BLUEWAVE HOTELS PVT LTD | E46: =Invoices!C43 -> bluewave - whitefield | F46: =IFERROR(INDEX(Customers!$F$4:$F$13,MATCH(TRIM(D46),Customers!$B$4:$B$13,0)),IFERROR(INDEX(Customers!$F$4:$F$13,MATCH(TRIM(D46),Customers!$C$4:$C$13,0)),0)) -> 2 | G46: =Invoices!E43 -> 46303 | H46: =$B$2-G46 -> -18 | I46: =IF(G46<$B$2,"OVERDUE","PENDING") -> PENDING | J46: =Invoices!F43 -> 12000 | K46: =ROUND(J46*F46/100,2) -> 240 | L46: =SUMIFS('Payment Lines'!$C$4:$C$60,'Payment Lines'!$B$4:$B$60,B46) -> 0 | M46: =SUMIFS('Payment Lines'!$D$4:$D$60,'Payment Lines'!$B$4:$B$60,B46) -> 0 | N46: =ROUND(L46+SUMIFS('Payment Lines'!$D$4:$D$60,'Payment Lines'!$B$4:$B$60,B46,'Payment Lines'!$E$4:$E$60,"CURRENT"),2) -> 0 | O46: =IF(U46="CANCEL",J46,ROUND(J46-N46,2)) -> 12000 | P46: =IF(U46="CANCEL","CANCELLED",IF(O46<=0,"PAID",IF(G46<$B$2,"OVERDUE",IF(N46>0,"PARTIAL","PENDING")))) -> PENDING | Q46: =IF(F46=0,0,MAX(0,ROUND(K46-M46,2))) -> 240 | R46: =IF(F46=0,"NOT_APPLICABLE",IF(AND(M46>=K46,K46>0),"CLEARED",IF(M46>0,"PARTIAL","PENDING"))) -> PENDING | S46: =COUNTIF('Payment Lines'!$B$4:$B$60,B46) -> 0 | T46: Leave unpaid. Must import and show Bluewave, TDS 240.
B49: Summary (final state after all payments and the cancel)
B50: PAID | C50: =COUNTIF($P$5:$P$46,B50) -> 16
B51: PARTIAL | C51: =COUNTIF($P$5:$P$46,B51) -> 2
B52: OVERDUE | C52: =COUNTIF($P$5:$P$46,B52) -> 8
B53: PENDING | C53: =COUNTIF($P$5:$P$46,B53) -> 15
B54: CANCELLED | C54: =COUNTIF($P$5:$P$46,B54) -> 1
B56: TDS CLEARED | C56: =COUNTIF($R$5:$R$46,"CLEARED") -> 14
B57: TDS PARTIAL | C57: =COUNTIF($R$5:$R$46,"PARTIAL") -> 1
B58: TDS PENDING | C58: =COUNTIF($R$5:$R$46,"PENDING") -> 16
B59: TDS NOT_APPLICABLE | C59: =COUNTIF($R$5:$R$46,"NOT_APPLICABLE") -> 11
B61: Invoices total | C61: =COUNTA($B$5:$B$46) -> 42
B62: Total amount (Rs) | C62: =SUM($J$5:$J$46) -> 11534687
B63: Status right after upload: OVERDUE | C63: =COUNTIF($I$5:$I$46,"OVERDUE") -> 11
...

Sheet Payments to Record
A1: Record these payments in this order (Accountant > Payments > Record Payment). Payment date can be any date; the reference date is on the Test Plan sheet.
A3: Order | B3: Payment ID | C3: Payment date | D3: Customer | E3: Payment mode | F3: Reference / UTR | G3: Cash received to TYPE (Rs) | H3: Extra cash not allocated (Rs) | I3: Total TDS (Rs) | J3: Total settlement (Rs) | K3: Unallocated in list (Rs) | L3: Invoices in payment | M3: Note
A4: 1 | B4: P01 | C4: 46281 | D4: Bluewave Hotels Pvt Ltd | E4: NEFT | F4: UTR-ALL-P01 | G4: =ROUND(SUMIFS('Payment Lines'!$C$4:$C$60,'Payment Lines'!$A$4:$A$60,B4)+H4,2) -> 49000 | H4: 0 | I4: =ROUND(SUMIFS('Payment Lines'!$D$4:$D$60,'Payment Lines'!$A$4:$A$60,B4),2) -> 1000 | J4: =ROUND(SUMIFS('Payment Lines'!$C$4:$C$60,'Payment Lines'!$A$4:$A$60,B4)+I4,2) -> 50000 | K4: =ROUND(H4,2) -> 0 | L4: =COUNTIF('Payment Lines'!$A$4:$A$60,B4) -> 1 | M4: Round 1
A5: 2 | B5: P02 | C5: 46281 | D5: Kaveri Tech Park LLP | E5: NEFT | F5: UTR-ALL-P02 | G5: =ROUND(SUMIFS('Payment Lines'!$C$4:$C$60,'Payment Lines'!$A$4:$A$60,B5)+H5,2) -> 90000 | H5: 0 | I5: =ROUND(SUMIFS('Payment Lines'!$D$4:$D$60,'Payment Lines'!$A$4:$A$60,B5),2) -> 10000 | J5: =ROUND(SUMIFS('Payment Lines'!$C$4:$C$60,'Payment Lines'!$A$4:$A$60,B5)+I5,2) -> 100000 | K5: =ROUND(H5,2) -> 0 | L5: =COUNTIF('Payment Lines'!$A$4:$A$60,B5) -> 1
A6: 3 | B6: P03 | C6: 46281 | D6: Green Meadow School | E6: UPI | F6: UTR-ALL-P03 | G6: =ROUND(SUMIFS('Payment Lines'!$C$4:$C$60,'Payment Lines'!$A$4:$A$60,B6)+H6,2) -> 39400 | H6: 0 | I6: =ROUND(SUMIFS('Payment Lines'!$D$4:$D$60,'Payment Lines'!$A$4:$A$60,B6),2) -> 600 | J6: =ROUND(SUMIFS('Payment Lines'!$C$4:$C$60,'Payment Lines'!$A$4:$A$60,B6)+I6,2) -> 40000 | K6: =ROUND(H6,2) -> 0 | L6: =COUNTIF('Payment Lines'!$A$4:$A$60,B6) -> 1
A7: 4 | B7: P04 | C7: 46281 | D7: Bluewave Hotels Pvt Ltd | E7: BANK_TRANSFER | F7: UTR-ALL-P04 | G7: =ROUND(SUMIFS('Payment Lines'!$C$4:$C$60,'Payment Lines'!$A$4:$A$60,B7)+H7,2) -> 30000 | H7: 0 | I7: =ROUND(SUMIFS('Payment Lines'!$D$4:$D$60,'Payment Lines'!$A$4:$A$60,B7),2) -> 0 | J7: =ROUND(SUMIFS('Payment Lines'!$C$4:$C$60,'Payment Lines'!$A$4:$A$60,B7)+I7,2) -> 30000 | K7: =ROUND(H7,2) -> 0 | L7: =COUNTIF('Payment Lines'!$A$4:$A$60,B7) -> 1
A8: 5 | B8: P05 | C8: 46281 | D8: Kaveri Tech Park LLP | E8: CHEQUE | F8: CHQ-ALL-P05 | G8: =ROUND(SUMIFS('Payment Lines'!$C$4:$C$60,'Payment Lines'!$A$4:$A$60,B8)+H8,2) -> 20000 | H8: 0 | I8: =ROUND(SUMIFS('Payment Lines'!$D$4:$D$60,'Payment Lines'!$A$4:$A$60,B8),2) -> 0 | J8: =ROUND(SUMIFS('Payment Lines'!$C$4:$C$60,'Payment Lines'!$A$4:$A$60,B8)+I8,2) -> 20000 | K8: =ROUND(H8,2) -> 0 | L8: =COUNTIF('Payment Lines'!$A$4:$A$60,B8) -> 1
A9: 6 | B9: P06 | C9: 46281 | D9: Lotus Diagnostics Centre | E9: NEFT | F9: UTR-ALL-P06 | G9: =ROUND(SUMIFS('Payment Lines'!$C$4:$C$60,'Payment Lines'!$A$4:$A$60,B9)+H9,2) -> 20000 | H9: 0 | I9: =ROUND(SUMIFS('Payment Lines'!$D$4:$D$60,'Payment Lines'!$A$4:$A$60,B9),2) -> 0 | J9: =ROUND(SUMIFS('Payment Lines'!$C$4:$C$60,'Payment Lines'!$A$4:$A$60,B9)+I9,2) -> 20000 | K9: =ROUND(H9,2) -> 0 | L9: =COUNTIF('Payment Lines'!$A$4:$A$60,B9) -> 1
A10: 7 | B10: P07 | C10: 46281 | D10: Bluewave Hotels Pvt Ltd | E10: BANK_TRANSFER | F10: UTR-ALL-P07 | G10: =ROUND(SUMIFS('Payment Lines'!$C$4:$C$60,'Payment Lines'!$A$4:$A$60,B10)+H10,2) -> 29400 | H10: 0 | I10: =ROUND(SUMIFS('Payment Lines'!$D$4:$D$60,'Payment Lines'!$A$4:$A$60,B10),2) -> 600 | J10: =ROUND(SUMIFS('Payment Lines'!$C$4:$C$60,'Payment Lines'!$A$4:$A$60,B10)+I10,2) -> 30000 | K10: =ROUND(H10,2) -> 0 | L10: =COUNTIF('Payment Lines'!$A$4:$A$60,B10) -> 1
A11: 8 | B11: P08 | C11: 46281 | D11: Sunrise Apartments Owners Assn | E11: UPI | F11: UTR-ALL-P08 | G11: =ROUND(SUMIFS('Payment Lines'!$C$4:$C$60,'Payment Lines'!$A$4:$A$60,B11)+H11,2) -> 10000 | H11: 0 | I11: =ROUND(SUMIFS('Payment Lines'!$D$4:$D$60,'Payment Lines'!$A$4:$A$60,B11),2) -> 0 | J11: =ROUND(SUMIFS('Payment Lines'!$C$4:$C$60,'Payment Lines'!$A$4:$A$60,B11)+I11,2) -> 10000 | K11: =ROUND(H11,2) -> 0 | L11: =COUNTIF('Payment Lines'!$A$4:$A$60,B11) -> 1
A12: 9 | B12: P09 | C12: 46281 | D12: Bluewave Hotels Pvt Ltd | E12: NEFT | F12: UTR-ALL-P09 | G12: =ROUND(SUMIFS('Payment Lines'!$C$4:$C$60,'Payment Lines'!$A$4:$A$60,B12)+H12,2) -> 54000 | H12: 0 | I12: =ROUND(SUMIFS('Payment Lines'!$D$4:$D$60,'Payment Lines'!$A$4:$A$60,B12),2) -> 1200 | J12: =ROUND(SUMIFS('Payment Lines'!$C$4:$C$60,'Payment Lines'!$A$4:$A$60,B12)+I12,2) -> 55200 | K12: =ROUND(H12,2) -> 0 | L12: =COUNTIF('Payment Lines'!$A$4:$A$60,B12) -> 3 | M12: One payment, three invoices
A13: 10 | B13: P10 | C13: 46281 | D13: Lotus Diagnostics Centre | E13: CARD | F13: CARD-ALL-P10 | G13: =ROUND(SUMIFS('Payment Lines'!$C$4:$C$60,'Payment Lines'!$A$4:$A$60,B13)+H13,2) -> 20000 | H13: 5300 | I13: =ROUND(SUMIFS('Payment Lines'!$D$4:$D$60,'Payment Lines'!$A$4:$A$60,B13),2) -> 300 | J13: =ROUND(SUMIFS('Payment Lines'!$C$4:$C$60,'Payment Lines'!$A$4:$A$60,B13)+I13,2) -> 15000 | K13: =ROUND(H13,2) -> 5300 | L13: =COUNTIF('Payment Lines'!$A$4:$A$60,B13) -> 1 | M13: Advance: cash typed 20,000
A14: 11 | B14: P11 | C14: 46281 | D14: Café Zoë & Sons (Pvt) Ltd | E14: CASH | F14: RCPT-ALL-P11 | G14: =ROUND(SUMIFS('Payment Lines'!$C$4:$C$60,'Payment Lines'!$A$4:$A$60,B14)+H14,2) -> 7000 | H14: 0 | I14: =ROUND(SUMIFS('Payment Lines'!$D$4:$D$60,'Payment Lines'!$A$4:$A$60,B14),2) -> 0 | J14: =ROUND(SUMIFS('Payment Lines'!$C$4:$C$60,'Payment Lines'!$A$4:$A$60,B14)+I14,2) -> 7000 | K14: =ROUND(H14,2) -> 0 | L14: =COUNTIF('Payment Lines'!$A$4:$A$60,B14) -> 1
A15: 12 | B15: P12 | C15: 46281 | D15: Bluewave Hotels Pvt Ltd | E15: NEFT | F15: UTR-ALL-P12 | G15: =ROUND(SUMIFS('Payment Lines'!$C$4:$C$60,'Payment Lines'!$A$4:$A$60,B15)+H15,2) -> 32666.34 | H15: 0 | I15: =ROUND(SUMIFS('Payment Lines'!$D$4:$D$60,'Payment Lines'!$A$4:$A$60,B15),2) -> 666.66 | J15: =ROUND(SUMIFS('Payment Lines'!$C$4:$C$60,'Payment Lines'!$A$4:$A$60,B15)+I15,2) -> 33333 | K15: =ROUND(H15,2) -> 0 | L15: =COUNTIF('Payment Lines'!$A$4:$A$60,B15) -> 1 | M15: Rounding
A16: 13 | B16: P13 | C16: 46281 | D16: Kaveri Tech Park LLP | E16: NEFT | F16: UTR-ALL-P13 | G16: =ROUND(SUMIFS('Payment Lines'!$C$4:$C$60,'Payment Lines'!$A$4:$A$60,B16)+H16,2) -> 41111.01 | H16: 0 | I16: =ROUND(SUMIFS('Payment Lines'!$D$4:$D$60,'Payment Lines'!$A$4:$A$60,B16),2) -> 4567.89 | J16: =ROUND(SUMIFS('Payment Lines'!$C$4:$C$60,'Payment Lines'!$A$4:$A$60,B16)+I16,2) -> 45678.9 | K16: =ROUND(H16,2) -> 0 | L16: =COUNTIF('Payment Lines'!$A$4:$A$60,B16) -> 1 | M16: Rounding
A17: 14 | B17: P14 | C17: 46281 | D17: Lotus Diagnostics Centre | E17: UPI | F17: UTR-ALL-P14 | G17: =ROUND(SUMIFS('Payment Lines'!$C$4:$C$60,'Payment Lines'!$A$4:$A$60,B17)+H17,2) -> 1209.87 | H17: 0 | I17: =ROUND(SUMIFS('Payment Lines'!$D$4:$D$60,'Payment Lines'!$A$4:$A$60,B17),2) -> 24.69 | J17: =ROUND(SUMIFS('Payment Lines'!$C$4:$C$60,'Payment Lines'!$A$4:$A$60,B17)+I17,2) -> 1234.56 | K17: =ROUND(H17,2) -> 0 | L17: =COUNTIF('Payment Lines'!$A$4:$A$60,B17) -> 1 | M17: Rounding
A18: 15 | B18: P15 | C18: 46281 | D18: Green Meadow School | E18: BANK_TRANSFER | F18: UTR-ALL-P15 | G18: =ROUND(SUMIFS('Payment Lines'!$C$4:$C$60,'Payment Lines'!$A$4:$A$60,B18)+H18,2) -> 8619.49 | H18: 0 | I18: =ROUND(SUMIFS('Payment Lines'!$D$4:$D$60,'Payment Lines'!$A$4:$A$60,B18),2) -> 131.26 | J18: =ROUND(SUMIFS('Payment Lines'!$C$4:$C$60,'Payment Lines'!$A$4:$A$60,B18)+I18,2) -> 8750.75 | K18: =ROUND(H18,2) -> 0 | L18: =COUNTIF('Payment Lines'!$A$4:$A$60,B18) -> 1 | M18: Rounding
A19: 16 | B19: P16 | C19: 46281 | D19: Café Zoë & Sons (Pvt) Ltd | E19: CASH | F19: RCPT-ALL-P16 | G19: =ROUND(SUMIFS('Payment Lines'!$C$4:$C$60,'Payment Lines'!$A$4:$A$60,B19)+H19,2) -> 0.01 | H19: 0 | I19: =ROUND(SUMIFS('Payment Lines'!$D$4:$D$60,'Payment Lines'!$A$4:$A$60,B19),2) -> 0 | J19: =ROUND(SUMIFS('Payment Lines'!$C$4:$C$60,'Payment Lines'!$A$4:$A$60,B19)+I19,2) -> 0.01 | K19: =ROUND(H19,2) -> 0 | L19: =COUNTIF('Payment Lines'!$A$4:$A$60,B19) -> 1 | M19: Smallest amount
A20: 17 | B20: P17 | C20: 46283 | D20: Bluewave Hotels Pvt Ltd | E20: NEFT | F20: UTR-ALL-P17 | G20: =ROUND(SUMIFS('Payment Lines'!$C$4:$C$60,'Payment Lines'!$A$4:$A$60,B20)+H20,2) -> 9800 | H20: 0 | I20: =ROUND(SUMIFS('Payment Lines'!$D$4:$D$60,'Payment Lines'!$A$4:$A$60,B20),2) -> 800 | J20: =ROUND(SUMIFS('Payment Lines'!$C$4:$C$60,'Payment Lines'!$A$4:$A$60,B20)+I20,2) -> 10600 | K20: =ROUND(H20,2) -> 0 | L20: =COUNTIF('Payment Lines'!$A$4:$A$60,B20) -> 2 | M20: Round 2: finishes one invoice + previous TDS
A21: 18 | B21: P18 | C21: 46283 | D21: Kaveri Tech Park LLP | E21: NEFT | F21: UTR-ALL-P18 | G21: =ROUND(SUMIFS('Payment Lines'!$C$4:$C$60,'Payment Lines'!$A$4:$A$60,B21)+H21,2) -> 27000 | H21: 0 | I21: =ROUND(SUMIFS('Payment Lines'!$D$4:$D$60,'Payment Lines'!$A$4:$A$60,B21),2) -> 5000 | J21: =ROUND(SUMIFS('Payment Lines'!$C$4:$C$60,'Payment Lines'!$A$4:$A$60,B21)+I21,2) -> 32000 | K21: =ROUND(H21,2) -> 0 | L21: =COUNTIF('Payment Lines'!$A$4:$A$60,B21) -> 2 | M21: Round 2: partial + previous TDS
A22: 19 | B22: P19 | C22: 46283 | D22: Sunrise Apartments Owners Assn | E22: UPI | F22: UTR-ALL-P19 | G22: =ROUND(SUMIFS('Payment Lines'!$C$4:$C$60,'Payment Lines'!$A$4:$A$60,B22)+H22,2) -> 15000 | H22: 0 | I22: =ROUND(SUMIFS('Payment Lines'!$D$4:$D$60,'Payment Lines'!$A$4:$A$60,B22),2) -> 0 | J22: =ROUND(SUMIFS('Payment Lines'!$C$4:$C$60,'Payment Lines'!$A$4:$A$60,B22)+I22,2) -> 15000 | K22: =ROUND(H22,2) -> 0 | L22: =COUNTIF('Payment Lines'!$A$4:$A$60,B22) -> 1 | M22: Round 2
B23: TOTAL | G23: =SUM(G4:G22) -> 504206.72 | I23: =SUM(I4:I22) -> 24890.5 | J23: =SUM(J4:J22) -> 523797.22 | K23: =SUM(K4:K22) -> 5300

Sheet Payment Lines
A1: What to type on each payment (one line per invoice in the payment)
A3: Payment ID | B3: Invoice No | C3: Cash (Rs) | D3: TDS (Rs) | E3: Type | F3: Note
A4: P01 | B4: ALL-2026-020 | C4: 49000 | D4: 1000 | E4: CURRENT
A5: P02 | B5: ALL-2026-021 | C5: 90000 | D5: 10000 | E5: CURRENT
A6: P03 | B6: ALL-2026-022 | C6: 39400 | D6: 600 | E6: CURRENT
A7: P04 | B7: ALL-2026-023 | C7: 30000 | D7: 0 | E7: CURRENT | F7: no TDS deducted
A8: P05 | B8: ALL-2026-024 | C8: 20000 | D8: 0 | E8: CURRENT | F8: no TDS deducted
A9: P06 | B9: ALL-2026-025 | C9: 20000 | D9: 0 | E9: CURRENT | F9: partial, invoice is overdue
A10: P07 | B10: ALL-2026-026 | C10: 29400 | D10: 600 | E10: CURRENT | F10: partial
A11: P08 | B11: ALL-2026-027 | C11: 10000 | D11: 0 | E11: CURRENT | F11: partial, no TDS customer
A12: P09 | B12: ALL-2026-028 | C12: 19600 | D12: 400 | E12: CURRENT | F12: line 1 of 3
A13: P09 | B13: ALL-2026-029 | C13: 29400 | D13: 600 | E13: CURRENT | F13: line 2 of 3
A14: P09 | B14: ALL-2026-030 | C14: 5000 | D14: 200 | E14: CURRENT | F14: line 3 of 3, part paid
A15: P10 | B15: ALL-2026-031 | C15: 14700 | D15: 300 | E15: CURRENT | F15: cash typed is 20,000; 5,300 stays unallocated
A16: P11 | B16: ALL-2026-033 | C16: 7000 | D16: 0 | E16: CURRENT
A17: P12 | B17: ALL-2026-034 | C17: 32666.34 | D17: 666.66 | E17: CURRENT
A18: P13 | B18: ALL-2026-035 | C18: 41111.01 | D18: 4567.89 | E18: CURRENT
A19: P14 | B19: ALL-2026-036 | C19: 1209.87 | D19: 24.69 | E19: CURRENT
A20: P15 | B20: ALL-2026-037 | C20: 8619.49 | D20: 131.26 | E20: CURRENT
A21: P16 | B21: ALL-2026-038 | C21: 0.01 | D21: 0 | E21: CURRENT
A22: P17 | B22: ALL-2026-026 | C22: 9800 | D22: 200 | E22: CURRENT | F22: second payment finishes the invoice
A23: P17 | B23: ALL-2026-023 | C23: 0 | D23: 600 | E23: PREVIOUS | F23: previous TDS on an invoice already paid in cash
A24: P18 | B24: ALL-2026-002 | C24: 27000 | D24: 3000 | E24: CURRENT | F24: partial with TDS on a big invoice
A25: P18 | B25: ALL-2026-024 | C25: 0 | D25: 2000 | E25: PREVIOUS | F25: previous TDS on an invoice already paid in cash
A26: P19 | B26: ALL-2026-027 | C26: 15000 | D26: 0 | E26: CURRENT | F26: second part-payment finishes the invoice

Sheet Customers
A1: Customers used in this file (already created in the test database)
A3: ID | B3: Customer name | C3: Customer code | D3: TDS applicable | E3: Type | F3: TDS rate % | G3: Notes
A4: C01 | B4: Bluewave Hotels Pvt Ltd | C4: BWH01 | D4: Yes | F4: 2 | G4: used in the Invoices sheet
A5: C02 | B5: Sunrise Apartments Owners Assn | C5: SAO02 | D5: No | F5: 0 | G5: used in the Invoices sheet
A6: C03 | B6: Kaveri Tech Park LLP | C6: KTP03 | D6: Yes | F6: 10 | G6: used in the Invoices sheet
A7: C04 | B7: Green Meadow School | C7: GMS04 | D7: Yes | F7: 1.5 | G7: used in the Invoices sheet
A8: C05 | B8: Lotus Diagnostics Centre | C8: LDC05 | D8: Yes | F8: 2 | G8: used in the Invoices sheet
A9: C06 | B9: Café Zoë & Sons (Pvt) Ltd | C9: CZS06 | D9: No | F9: 0 | G9: used in the Invoices sheet
A10: C07 | B10: Twin Traders | C10: TWN07A | D10: No | F10: 0 | G10: not used in this file
A11: C08 | B11: Twin Traders | C11: TWN07B | D11: No | F11: 0 | G11: not used in this file
A12: C09 | B12: Dormant Stores Ltd | C12: DRM09 | D12: No (inactive) | F12: 0 | G12: not used in this file
A13: C10 | B13: Southern Foods Co | C13: SFC10 | D13: No (other branch) | F13: 0 | G13: not used in this file

Sheet Read Me
A1: Invoice upload - ALL CASES
A2: What this is | B2: One file that covers every case: TDS 2% / 10% / 1.5% customers and no-TDS customers, invoices that are overdue (1 to 200 days), due today, due this week / month, not yet due, payments (full, partial, TDS deducted, TDS missed then added later, one payment for many invoices, advance), cancel, rounding, small and large amounts. Every cell is filled. All data is random.
A3: Sheet 'Invoices' | B3: The file to UPLOAD. It is the first sheet and has exactly the template columns (Invoice No, Customer, Site, Invoice Date, Due Date, Amount, Remarks). The other sheets are only for you; the importer reads the first sheet only.
A4: Before you upload | B4: The customers and sites in this file were added to the test database (codes BWH01, SAO02, KTP03, GMS04, LDC05, CZS06). TDS rates are already set: Bluewave 2%, Kaveri 10%, Green Meadow 1.5%, Lotus 2%; Sunrise and Cafe Zoe have no TDS.
A5: Step 1 - upload | B5: Invoice Upload > choose this file > Upload & Validate. Review & Validate should show 42 total, 42 valid, 0 errors. Click Submit.
A6: Step 2 - check | B6: Invoice List: 11 invoices are past their due date and show OVERDUE, the other 31 show PENDING (see 'Test Plan' column 'Status right after upload'). Also compare 'Expected TDS'.
A7: Step 3 - record payments | B7: Follow 'Payments to Record' in order (P01 to P19). The 'Payment Lines' sheet gives the cash and TDS to type on each invoice. Round 2 payments (P17-P19) must come after round 1.
A8: Step 4 - compare | B8: After the payments, the 'Test Plan' sheet shows the final status, pending amount and TDS for every invoice. The Summary at the bottom gives the expected counts (PAID, PARTIAL, OVERDUE, PENDING, CANCELLED).
A9: Cancel | B9: Case 32 (ALL-2026-032): cancel it from its details page, do not pay it. Case 33 (ALL-2026-033): after payment P11, try to cancel it - the app must refuse.
A10: Reference date | B10: Days late/left and OVERDUE are worked out from the reference date on 'Test Plan' cell B2 (20/09/2026). If you test on a later day, invoices get older: change B2 to today and the expected numbers update. The due dates in the Invoices sheet are fixed.
A11: Submitting twice | B11: Uploading this file a second time makes every row a duplicate ('already has this invoice'). Use it once, or delete the invoices first.
