Workbook

Sheet Read Me
A1: Accountant panel - test cases
A2: Scope | B2: Only the accountant panel: login and menu, dashboard, invoice upload, review and submit, row validation, invoice list and details, the five invoice statuses, outstanding, record payment, payment list, TDS, tasks, layout and responsive checks, security, database checks and end-to-end scenarios. Admin, supervisor, technician and client panels are not included.
A3: Reflects the current app | B3: Upload only checks the file; nothing is saved until you click Submit on Review & Validate. A 'Successfully uploaded' pop-up appears after upload. Overdue is stored in the database as well as shown on screen. The menu item is TDS. The payment field is UTR No. Add Previous TDS enables only when a fully paid invoice still has TDS pending.
A4: How to use | B4: 1) Filter 'Test Cases' by Module, Type or Priority. 2) Follow the steps with the data named in 'Test Data'. 3) Compare with 'Expected Result', write what you saw in 'Actual Result' and choose a Status. 4) Put failures in 'Defect Log'. 5) 'Summary' updates by itself.
A5: Status values | B5: Not Run (default), Pass, Fail, Blocked, Skipped. Pass % = Pass / (Pass + Fail + Blocked).
A6: Priority | B6: P1 Critical (money, TDS, statuses, security, data loss) · P2 High · P3 Medium · P4 Low.
A7: Basis column | B7: Code = the behaviour was read from the repository and checked. Design = the agreed TDS design. Standard = good practice; the exact behaviour is not fixed in code, so record what you see.
A8: Test data | B8: All customers, sites and invoices are made up. The upload files are in docs/test-data/upload-pack/. The customers and sites exist in the test database (see 'Test Data'). Nothing was taken from real data.
A9: Run order | B9: 1) Set up the test customers (already done in the database). 2) Upload and Submit ALL_CASES_invoice_upload_TDS2pct.xlsx. 3) Run the payments from its 'Payments to Record' sheet. 4) Then the validation, edge, five-status and file-level files. Submit ALL_CASES before VALIDATION, because one validation row repeats an invoice number from it.
A10: Known gaps to decide | B10: • The accountant panel has no Cancel button for an invoice. • Payment List shows cash only, not TDS. • The TDS page accepts any rate from 0 to 100 (only 2% is meant to be used). • Payment Tracking and Customer Outstanding are not in the menu (URL only). • A remark longer than 1000 characters or an amount with more than 2 decimals is accepted by the review but may behave oddly on Submit (see the EDGE file).

Sheet Summary
A1: Execution summary (updates from the Test Cases sheet)
A3: Module | B3: Total | C3: Pass | D3: Fail | E3: Blocked | F3: Skipped | G3: Not Run | H3: Progress % | I3: Pass %
A4: Login, Menu & Access | B4: =COUNTIF('Test Cases'!$B:$B,$A4) -> 16 | C4: =COUNTIFS('Test Cases'!$B:$B,$A4,'Test Cases'!$M:$M,"Pass") -> 0 | D4: =COUNTIFS('Test Cases'!$B:$B,$A4,'Test Cases'!$M:$M,"Fail") -> 0 | E4: =COUNTIFS('Test Cases'!$B:$B,$A4,'Test Cases'!$M:$M,"Blocked") -> 0 | F4: =COUNTIFS('Test Cases'!$B:$B,$A4,'Test Cases'!$M:$M,"Skipped") -> 0 | G4: =COUNTIFS('Test Cases'!$B:$B,$A4,'Test Cases'!$M:$M,"Not Run") -> 16 | H4: =IFERROR((C4+D4+E4)/B4,0) -> 0 | I4: =IFERROR(C4/(C4+D4+E4),0) -> 0
A5: Dashboard | B5: =COUNTIF('Test Cases'!$B:$B,$A5) -> 24 | C5: =COUNTIFS('Test Cases'!$B:$B,$A5,'Test Cases'!$M:$M,"Pass") -> 0 | D5: =COUNTIFS('Test Cases'!$B:$B,$A5,'Test Cases'!$M:$M,"Fail") -> 0 | E5: =COUNTIFS('Test Cases'!$B:$B,$A5,'Test Cases'!$M:$M,"Blocked") -> 0 | F5: =COUNTIFS('Test Cases'!$B:$B,$A5,'Test Cases'!$M:$M,"Skipped") -> 0 | G5: =COUNTIFS('Test Cases'!$B:$B,$A5,'Test Cases'!$M:$M,"Not Run") -> 24 | H5: =IFERROR((C5+D5+E5)/B5,0) -> 0 | I5: =IFERROR(C5/(C5+D5+E5),0) -> 0
A6: Invoice Upload | B6: =COUNTIF('Test Cases'!$B:$B,$A6) -> 25 | C6: =COUNTIFS('Test Cases'!$B:$B,$A6,'Test Cases'!$M:$M,"Pass") -> 0 | D6: =COUNTIFS('Test Cases'!$B:$B,$A6,'Test Cases'!$M:$M,"Fail") -> 0 | E6: =COUNTIFS('Test Cases'!$B:$B,$A6,'Test Cases'!$M:$M,"Blocked") -> 0 | F6: =COUNTIFS('Test Cases'!$B:$B,$A6,'Test Cases'!$M:$M,"Skipped") -> 0 | G6: =COUNTIFS('Test Cases'!$B:$B,$A6,'Test Cases'!$M:$M,"Not Run") -> 25 | H6: =IFERROR((C6+D6+E6)/B6,0) -> 0 | I6: =IFERROR(C6/(C6+D6+E6),0) -> 0
A7: Review & Validate and Submit | B7: =COUNTIF('Test Cases'!$B:$B,$A7) -> 23 | C7: =COUNTIFS('Test Cases'!$B:$B,$A7,'Test Cases'!$M:$M,"Pass") -> 0 | D7: =COUNTIFS('Test Cases'!$B:$B,$A7,'Test Cases'!$M:$M,"Fail") -> 0 | E7: =COUNTIFS('Test Cases'!$B:$B,$A7,'Test Cases'!$M:$M,"Blocked") -> 0 | F7: =COUNTIFS('Test Cases'!$B:$B,$A7,'Test Cases'!$M:$M,"Skipped") -> 0 | G7: =COUNTIFS('Test Cases'!$B:$B,$A7,'Test Cases'!$M:$M,"Not Run") -> 23 | H7: =IFERROR((C7+D7+E7)/B7,0) -> 0 | I7: =IFERROR(C7/(C7+D7+E7),0) -> 0
A8: Row Validation (per row of the upload) | B8: =COUNTIF('Test Cases'!$B:$B,$A8) -> 47 | C8: =COUNTIFS('Test Cases'!$B:$B,$A8,'Test Cases'!$M:$M,"Pass") -> 0 | D8: =COUNTIFS('Test Cases'!$B:$B,$A8,'Test Cases'!$M:$M,"Fail") -> 0 | E8: =COUNTIFS('Test Cases'!$B:$B,$A8,'Test Cases'!$M:$M,"Blocked") -> 0 | F8: =COUNTIFS('Test Cases'!$B:$B,$A8,'Test Cases'!$M:$M,"Skipped") -> 0 | G8: =COUNTIFS('Test Cases'!$B:$B,$A8,'Test Cases'!$M:$M,"Not Run") -> 47 | H8: =IFERROR((C8+D8+E8)/B8,0) -> 0 | I8: =IFERROR(C8/(C8+D8+E8),0) -> 0
A9: Invoice List & Invoice Details | B9: =COUNTIF('Test Cases'!$B:$B,$A9) -> 20 | C9: =COUNTIFS('Test Cases'!$B:$B,$A9,'Test Cases'!$M:$M,"Pass") -> 0 | D9: =COUNTIFS('Test Cases'!$B:$B,$A9,'Test Cases'!$M:$M,"Fail") -> 0 | E9: =COUNTIFS('Test Cases'!$B:$B,$A9,'Test Cases'!$M:$M,"Blocked") -> 0 | F9: =COUNTIFS('Test Cases'!$B:$B,$A9,'Test Cases'!$M:$M,"Skipped") -> 0 | G9: =COUNTIFS('Test Cases'!$B:$B,$A9,'Test Cases'!$M:$M,"Not Run") -> 20 | H9: =IFERROR((C9+D9+E9)/B9,0) -> 0 | I9: =IFERROR(C9/(C9+D9+E9),0) -> 0
A10: Invoice Status (five statuses) | B10: =COUNTIF('Test Cases'!$B:$B,$A10) -> 21 | C10: =COUNTIFS('Test Cases'!$B:$B,$A10,'Test Cases'!$M:$M,"Pass") -> 0 | D10: =COUNTIFS('Test Cases'!$B:$B,$A10,'Test Cases'!$M:$M,"Fail") -> 0 | E10: =COUNTIFS('Test Cases'!$B:$B,$A10,'Test Cases'!$M:$M,"Blocked") -> 0 | F10: =COUNTIFS('Test Cases'!$B:$B,$A10,'Test Cases'!$M:$M,"Skipped") -> 0 | G10: =COUNTIFS('Test Cases'!$B:$B,$A10,'Test Cases'!$M:$M,"Not Run") -> 21 | H10: =IFERROR((C10+D10+E10)/B10,0) -> 0 | I10: =IFERROR(C10/(C10+D10+E10),0) -> 0
A11: Outstanding, Customer Outstanding & Payment Tracking | B11: =COUNTIF('Test Cases'!$B:$B,$A11) -> 13 | C11: =COUNTIFS('Test Cases'!$B:$B,$A11,'Test Cases'!$M:$M,"Pass") -> 0 | D11: =COUNTIFS('Test Cases'!$B:$B,$A11,'Test Cases'!$M:$M,"Fail") -> 0 | E11: =COUNTIFS('Test Cases'!$B:$B,$A11,'Test Cases'!$M:$M,"Blocked") -> 0 | F11: =COUNTIFS('Test Cases'!$B:$B,$A11,'Test Cases'!$M:$M,"Skipped") -> 0 | G11: =COUNTIFS('Test Cases'!$B:$B,$A11,'Test Cases'!$M:$M,"Not Run") -> 13 | H11: =IFERROR((C11+D11+E11)/B11,0) -> 0 | I11: =IFERROR(C11/(C11+D11+E11),0) -> 0
A12: Record Payment | B12: =COUNTIF('Test Cases'!$B:$B,$A12) -> 42 | C12: =COUNTIFS('Test Cases'!$B:$B,$A12,'Test Cases'!$M:$M,"Pass") -> 0 | D12: =COUNTIFS('Test Cases'!$B:$B,$A12,'Test Cases'!$M:$M,"Fail") -> 0 | E12: =COUNTIFS('Test Cases'!$B:$B,$A12,'Test Cases'!$M:$M,"Blocked") -> 0 | F12: =COUNTIFS('Test Cases'!$B:$B,$A12,'Test Cases'!$M:$M,"Skipped") -> 0 | G12: =COUNTIFS('Test Cases'!$B:$B,$A12,'Test Cases'!$M:$M,"Not Run") -> 42 | H12: =IFERROR((C12+D12+E12)/B12,0) -> 0 | I12: =IFERROR(C12/(C12+D12+E12),0) -> 0
A13: Payment List | B13: =COUNTIF('Test Cases'!$B:$B,$A13) -> 10 | C13: =COUNTIFS('Test Cases'!$B:$B,$A13,'Test Cases'!$M:$M,"Pass") -> 0 | D13: =COUNTIFS('Test Cases'!$B:$B,$A13,'Test Cases'!$M:$M,"Fail") -> 0 | E13: =COUNTIFS('Test Cases'!$B:$B,$A13,'Test Cases'!$M:$M,"Blocked") -> 0 | F13: =COUNTIFS('Test Cases'!$B:$B,$A13,'Test Cases'!$M:$M,"Skipped") -> 0 | G13: =COUNTIFS('Test Cases'!$B:$B,$A13,'Test Cases'!$M:$M,"Not Run") -> 10 | H13: =IFERROR((C13+D13+E13)/B13,0) -> 0 | I13: =IFERROR(C13/(C13+D13+E13),0) -> 0
A14: TDS | B14: =COUNTIF('Test Cases'!$B:$B,$A14) -> 19 | C14: =COUNTIFS('Test Cases'!$B:$B,$A14,'Test Cases'!$M:$M,"Pass") -> 0 | D14: =COUNTIFS('Test Cases'!$B:$B,$A14,'Test Cases'!$M:$M,"Fail") -> 0 | E14: =COUNTIFS('Test Cases'!$B:$B,$A14,'Test Cases'!$M:$M,"Blocked") -> 0 | F14: =COUNTIFS('Test Cases'!$B:$B,$A14,'Test Cases'!$M:$M,"Skipped") -> 0 | G14: =COUNTIFS('Test Cases'!$B:$B,$A14,'Test Cases'!$M:$M,"Not Run") -> 19 | H14: =IFERROR((C14+D14+E14)/B14,0) -> 0 | I14: =IFERROR(C14/(C14+D14+E14),0) -> 0
A15: Tasks & Reminders | B15: =COUNTIF('Test Cases'!$B:$B,$A15) -> 11 | C15: =COUNTIFS('Test Cases'!$B:$B,$A15,'Test Cases'!$M:$M,"Pass") -> 0 | D15: =COUNTIFS('Test Cases'!$B:$B,$A15,'Test Cases'!$M:$M,"Fail") -> 0 | E15: =COUNTIFS('Test Cases'!$B:$B,$A15,'Test Cases'!$M:$M,"Blocked") -> 0 | F15: =COUNTIFS('Test Cases'!$B:$B,$A15,'Test Cases'!$M:$M,"Skipped") -> 0 | G15: =COUNTIFS('Test Cases'!$B:$B,$A15,'Test Cases'!$M:$M,"Not Run") -> 11 | H15: =IFERROR((C15+D15+E15)/B15,0) -> 0 | I15: =IFERROR(C15/(C15+D15+E15),0) -> 0
... A19: End-to-End Scenarios | B19: =COUNTIF('Test Cases'!$B:$B,$A19) -> 6 | C19: =COUNTIFS('Test Cases'!$B:$B,$A19,'Test Cases'!$M:$M,"Pass") -> 0 | D19: =COUNTIFS('Test Cases'!$B:$B,$A19,'Test Cases'!$M:$M,"Fail") -> 0 | E19: =COUNTIFS('Test Cases'!$B:$B,$A19,'Test Cases'!$M:$M,"Blocked") -> 0 | F19: =COUNTIFS('Test Cases'!$B:$B,$A19,'Test Cases'!$M:$M,"Skipped") -> 0 | G19: =COUNTIFS('Test Cases'!$B:$B,$A19,'Test Cases'!$M:$M,"Not Run") -> 6 | H19: =IFERROR((C19+D19+E19)/B19,0) -> 0 | I19: =IFERROR(C19/(C19+D19+E19),0) -> 0
A20: TOTAL | B20: =SUM(B4:B19) -> 355 | C20: =SUM(C4:C19) -> 0 | D20: =SUM(D4:D19) -> 0 | E20: =SUM(E4:E19) -> 0 | F20: =SUM(F4:F19) -> 0 | G20: =SUM(G4:G19) -> 355 | H20: =IFERROR((C20+D20+E20)/B20,0) -> 0 | I20: =IFERROR(C20/(C20+D20+E20),0) -> 0
A22: By priority | B22: Total | C22: Pass | D22: Fail | E22: Blocked | F22: Skipped | G22: Not Run
A23: P1 | B23: =COUNTIF('Test Cases'!$F:$F,$A23) -> 158 | C23: =COUNTIFS('Test Cases'!$F:$F,$A23,'Test Cases'!$M:$M,"Pass") -> 0 | D23: =COUNTIFS('Test Cases'!$F:$F,$A23,'Test Cases'!$M:$M,"Fail") -> 0 | E23: =COUNTIFS('Test Cases'!$F:$F,$A23,'Test Cases'!$M:$M,"Blocked") -> 0 | F23: =COUNTIFS('Test Cases'!$F:$F,$A23,'Test Cases'!$M:$M,"Skipped") -> 0 | G23: =COUNTIFS('Test Cases'!$F:$F,$A23,'Test Cases'!$M:$M,"Not Run") -> 158
A24: P2 | B24: =COUNTIF('Test Cases'!$F:$F,$A24) -> 121 | C24: =COUNTIFS('Test Cases'!$F:$F,$A24,'Test Cases'!$M:$M,"Pass") -> 0 | D24: =COUNTIFS('Test Cases'!$F:$F,$A24,'Test Cases'!$M:$M,"Fail") -> 0 | E24: =COUNTIFS('Test Cases'!$F:$F,$A24,'Test Cases'!$M:$M,"Blocked") -> 0 | F24: =COUNTIFS('Test Cases'!$F:$F,$A24,'Test Cases'!$M:$M,"Skipped") -> 0 | G24: =COUNTIFS('Test Cases'!$F:$F,$A24,'Test Cases'!$M:$M,"Not Run") -> 121
A25: P3 | B25: =COUNTIF('Test Cases'!$F:$F,$A25) -> 51 | C25: =COUNTIFS('Test Cases'!$F:$F,$A25,'Test Cases'!$M:$M,"Pass") -> 0 | D25: =COUNTIFS('Test Cases'!$F:$F,$A25,'Test Cases'!$M:$M,"Fail") -> 0 | E25: =COUNTIFS('Test Cases'!$F:$F,$A25,'Test Cases'!$M:$M,"Blocked") -> 0 | F25: =COUNTIFS('Test Cases'!$F:$F,$A25,'Test Cases'!$M:$M,"Skipped") -> 0 | G25: =COUNTIFS('Test Cases'!$F:$F,$A25,'Test Cases'!$M:$M,"Not Run") -> 51
A26: P4 | B26: =COUNTIF('Test Cases'!$F:$F,$A26) -> 25 | C26: =COUNTIFS('Test Cases'!$F:$F,$A26,'Test Cases'!$M:$M,"Pass") -> 0 | D26: =COUNTIFS('Test Cases'!$F:$F,$A26,'Test Cases'!$M:$M,"Fail") -> 0 | E26: =COUNTIFS('Test Cases'!$F:$F,$A26,'Test Cases'!$M:$M,"Blocked") -> 0 | F26: =COUNTIFS('Test Cases'!$F:$F,$A26,'Test Cases'!$M:$M,"Skipped") -> 0 | G26: =COUNTIFS('Test Cases'!$F:$F,$A26,'Test Cases'!$M:$M,"Not Run") -> 25
A28: By type | B28: Total
A29: Boundary | B29: =COUNTIF('Test Cases'!$E:$E,$A29) -> 10
A30: Compatibility | B30: =COUNTIF('Test Cases'!$E:$E,$A30) -> 1
A31: Design | B31: =COUNTIF('Test Cases'!$E:$E,$A31) -> 6
A32: Functional | B32: =COUNTIF('Test Cases'!$E:$E,$A32) -> 132
A33: Integration | B33: =COUNTIF('Test Cases'!$E:$E,$A33) -> 25
A34: Negative | B34: =COUNTIF('Test Cases'!$E:$E,$A34) -> 25
A35: Performance | B35: =COUNTIF('Test Cases'!$E:$E,$A35) -> 1
A36: Responsive | B36: =COUNTIF('Test Cases'!$E:$E,$A36) -> 52
A37: Security | B37: =COUNTIF('Test Cases'!$E:$E,$A37) -> 19
A38: UI/UX | B38: =COUNTIF('Test Cases'!$E:$E,$A38) -> 32
A39: Usability | B39: =COUNTIF('Test Cases'!$E:$E,$A39) -> 2
A40: Validation | B40: =COUNTIF('Test Cases'!$E:$E,$A40) -> 50

Sheet Test Cases
A1: Test ID | B1: Module | C1: Screen / Area | D1: Scenario | E1: Type | F1: Priority | G1: Pre-condition | H1: Test Steps | I1: Test Data | J1: Expected Result | K1: Basis | L1: Actual Result | M1: Status | N1: Tester | O1: Executed On | P1: Defect ID / Remarks
A2: ACC-001 | B2: Login, Menu & Access | C2: Login | D2: Accountant logs in | E2: Functional | F2: P1 | G2: Accountant user is active | H2: 1. Open /login 2. Tick Terms 3. Enter the accountant email and password 4. Click Login | I2: Accountant user | J2: Lands on /accountant (dashboard); header shows 'Accountant Panel', bell icon and user icon | K2: Code | M2: Not Run
A3: ACC-002 | B3: Login, Menu & Access | C3: Login | D3: Wrong password | E3: Negative | F3: P1 | G3: - | H3: 1. Enter the accountant email with a wrong password | I3: Wrong@999 | J3: Alert 'Invalid credentials'; stays on /login | K3: Code | M3: Not Run
A4: ACC-003 | B4: Login, Menu & Access | C4: Login | D4: Login button disabled until Terms is ticked | E4: Validation | F4: P2 | G4: - | H4: 1. Fill email and password 2. Leave Terms unticked | I4: - | J4: Login button stays disabled | K4: Code | M4: Not Run
A5: ACC-004 | B5: Login, Menu & Access | C5: Session | D5: Refresh keeps the user logged in | E5: Functional | F5: P2 | G5: Logged in | H5: 1. Press F5 on Invoice List | I5: - | J5: Same page reloads; still logged in | K5: Standard | M5: Not Run
A6: ACC-005 | B6: Login, Menu & Access | C6: Session | D6: Logout | E6: Functional | F6: P1 | G6: Logged in | H6: 1. User icon > Logout 2. Press Back | I6: - | J6: Returns to /login; Back does not show a protected page | K6: Standard | M6: Not Run
A7: ACC-006 | B7: Login, Menu & Access | C7: Session | D7: Invalid or expired token | E7: Security | F7: P1 | G7: Logged in | H7: 1. Change the token in localStorage to random text 2. Click any menu item | I7: - | J7: Redirected to /login | K7: Code | M7: Not Run
A8: ACC-007 | B8: Login, Menu & Access | C8: Menu | D8: Sidebar items and order | E8: UI/UX | F8: P2 | G8: Logged in | H8: 1. Look at the sidebar | I8: - | J8: Dashboard; Invoices (Invoice Upload, Review & Validate, Invoice List, Outstanding); Payments (Record Payment, Payment List); Tasks & Reminders; TDS | K8: Code | M8: Not Run
A9: ACC-008 | B9: Login, Menu & Access | C9: Menu | D9: Every menu item opens the right page | E9: Functional | F9: P1 | G9: Logged in | H9: 1. Click each menu item in turn | I9: - | J9: Each opens its own page with a matching heading; the active item is highlighted | K9: Code | M9: Not Run
A10: ACC-009 | B10: Login, Menu & Access | C10: Menu | D10: Invoices and Payments groups expand and collapse | E10: UI/UX | F10: P3 | G10: - | H10: 1. Click Invoices and Payments | I10: - | J10: Sub-menus open and close | K10: Code | M10: Not Run
A11: ACC-010 | B11: Login, Menu & Access | C11: Menu | D11: Payment Tracking and Customer Outstanding are not in the menu | E11: Functional | F11: P3 | G11: - | H11: 1. Open /accountant/invoices/tracking and /accountant/payments/customer-outstanding by URL | I11: - | J11: Both pages open and work (they are reachable by URL only) | K11: Code | M11: Not Run
A12: ACC-011 | B12: Login, Menu & Access | C12: Access | D12: Other roles cannot open /accountant | E12: Security | F12: P1 | G12: Logged in as admin, supervisor, technician and client in turn | H12: 1. Type /accountant in the address bar | I12: Each role | J12: Redirected to that role's own home; accountant pages never shown | K12: Code | M12: Not Run
A13: ACC-012 | B13: Login, Menu & Access | C13: Access | D13: Not logged in | E13: Security | F13: P1 | G13: Logged out | H13: 1. Open /accountant/invoices/list | I13: - | J13: Redirected to /login | K13: Code | M13: Not Run
... A356: E2E-006 | B356: End-to-End Scenarios | C356: Dashboard flow | D356: Numbers move after each step | E356: Integration | F356: P2 | G356: - | H356: 1. Note the dashboard 2. Submit 3. Pay 4. Compare each time | I356: - | J356: Tiles and chart change exactly as expected after each step | K356: Code | M356: Not Run

Sheet Test Data
A1: A. Upload files (folder docs/test-data/upload-pack/)
A2: File | B2: What it is for | C2: Expected on the Review screen | D2: Notes
A3: ALL_CASES_invoice_upload_TDS2pct.xlsx | B3: 42 invoices covering every status, TDS (2%) and non-TDS customers, due-date edges. Extra sheets: Test Plan, Payments to Record, Payment Lines. | C3: 42 total, 42 valid, 0 errors | D3: Upload and Submit first. Do not upload twice (all rows would be duplicates).
A4: VALIDATION_all_cases_invoice_upload.xlsx | B4: Every validation rule, row by row. Second sheet 'Expected Results' lists the expected message for each row. | C4: 70 rows counted: 31 valid, 39 errors (one blank row is skipped) | D4: Submit ALL_CASES first (one row repeats an invoice number from it).
A5: EDGE_rows_to_observe.xlsx | B5: 5 rows that pass review but may behave oddly when saved (0.001 amount, 1001-character remark, far future dates). | C5: 5 total, 5 valid | D5: Do not include in a normal run.
A6: FIVE_STATUS_invoice_upload.xlsx | B6: 5 invoices, one for each status. Second sheet 'Status Plan'. | C6: 5 total, 5 valid | D6: Pay …/05889 5,000 and …/1233 10,499; cancel …/3456.
A7: file_level_checks/01_missing_columns.xlsx | B7: No Site and Amount column | C7: 'The file is missing these columns: Site, Amount. Please use the template.'
A8: file_level_checks/02_headers_only.xlsx | B8: Only the header row | C8: 'The file has no invoice rows.'
A9: file_level_checks/03_corrupt_file.xlsx | B9: Text renamed to .xlsx | C9: 'The file could not be read. Please upload a valid .xlsx or .csv file.'
A10: file_level_checks/04_wrong_type.pdf, 05_wrong_type.png | B10: Wrong file types | C10: Rejected: only .xlsx or .csv
A11: file_level_checks/06_over_5MB.xlsx | B11: 5.6 MB | C11: 'The file is too large (maximum 5 MB)'
A12: file_level_checks/07_5000_rows.xlsx | B12: Exactly 5000 rows | C12: 5000 total, 5000 valid | D12: Also a speed test; do not Submit unless you want 5000 invoices.
A13: file_level_checks/08_5001_rows.xlsx | B13: One row over the limit | C13: 'The file has more than 5000 rows. Please split it into smaller files.'
A14: file_level_checks/09_alternate_headers.xlsx | B14: Other header spellings, shuffled columns | C14: 8 total, 8 valid
A16: B. Test customers in the database (codes)
A17: Customer (code) | B17: TDS | C17: Branch / status | D17: Sites
A18: Bluewave Hotels Pvt Ltd (BWH01) | B18: 2% | C18: Head Office | D18: Bluewave - Indiranagar, - Whitefield, - Koramangala, - Old Warehouse (inactive)
A19: Sunrise Apartments Owners Assn (SAO02) | B19: none | C19: Head Office | D19: Sunrise - Tower A, - Tower B, - Clubhouse
A20: Kaveri Tech Park LLP (KTP03) | B20: 2% | C20: Head Office | D20: Kaveri - Block 1, - Block 2, - Food Court
A21: Green Meadow School (GMS04) | B21: 2% | C21: Head Office | D21: Green Meadow - Main Campus, - Annex
A22: Lotus Diagnostics Centre (LDC05) | B22: 2% | C22: Head Office | D22: Lotus - Jayanagar Lab, - HSR Lab
A23: Café Zoë & Sons (Pvt) Ltd (CZS06) | B23: none | C23: Head Office | D23: Café Zoë - Main Outlet, - Kiosk 2
A24: Twin Traders (TWN07A and TWN07B - same name) | B24: none | C24: Head Office | D24: Twin Traders - Shop 1 / Shop 2
A25: Dormant Stores Ltd (DRM09) | B25: none | C25: INACTIVE customer | D25: Dormant - Store
A26: Southern Foods Co (SFC10) | B26: none | C26: other branch (abc) | D26: Southern - Depot
A27: Orchid Bakers & Confectioners (OBC11) | B27: none | C27: Head Office | D27: Orchid - Central Bakery, - Mall Outlet
A28: Silverline Logistics Pvt Ltd (SLL12) | B28: 2% | C28: Head Office | D28: Silverline - Hub 1, - Hub 2
... A39: Narayana Hrudayalaya, OSB India Pvt Ltd, The Big Market, Cadabams Diagnostics LLP | B39: Narayana 2%, others none | C39: Head Office | D39: Electronic City, Telegana, chandapura, jayanagar, kanakapura (used by the FIVE_STATUS file)
A41: C. Invoice status rules
A42: Status | B42: Condition | C42: Set when | D42: Shown as
A43: PENDING | B43: Nothing settled, due date not passed (or no due date) | C43: Invoice is saved by Submit | D43: Pending
A44: PARTIAL | B44: Part settled, due date not passed | C44: A payment covers part of the invoice | D44: Partially Paid
A45: OVERDUE | B45: Not fully paid and the due date has passed | C45: Backend sync: at start-up, daily 00:05, and after upload Submit, payment, create or edit | D45: Overdue
A46: PAID | B46: Cash + TDS settled equals the invoice amount (pending 0) | C46: A payment settles the rest | D46: Paid
A47: CANCELLED | B47: Cancelled while nothing had been paid | C47: Cancel action (no button in the accountant panel) | D47: Cancelled
A49: D. TDS status rules (customer with 2% TDS)
A50: TDS status | B50: Condition | C50: Example (₹50,000 invoice)
A51: NOT_APPLICABLE | B51: Customer has no TDS when the invoice was saved | C51: -
A52: PENDING | B52: Nothing deducted yet | C52: Expected 1,000, deducted 0
A53: PARTIAL | B53: Some deducted, less than expected | C53: Deducted 500 of 1,000
...

Sheet Defect Log
A1: Defect ID | B1: Test ID | C1: Module | D1: Title | E1: Steps to reproduce | F1: Expected | G1: Actual | H1: Severity | I1: Status | J1: Reported by | K1: Date | L1: Assigned to | M1: Fixed in build | N1: Retest result
A2: DEF-001 | B2: PAY-030 | C2: Record Payment | D2: EXAMPLE: cash more than pending is accepted | E2: 1. Open Record Payment 2. Pending 30,000 3. Cash 31,000 4. Save | F2: Blocked with a message | G2: Payment saved | H2: High | I2: Open | J2: Tester | K2: 46286 | L2: Developer
